Workbook

Sheet Check
A1: sheet | B1: member_id | C1: measure | D1: Python | E1: Excel (formulas) | F1: difference
A2: Pensioner | B2: M0017 | C2: PV at flat rate | D2: 277066.39 | E2: =Pensioner!E3 | F2: =E2-D2
A3: Pensioner | B3: M0017 | C3: IAS 19 PV (curve) | D3: 267691.66 | E3: =Pensioner!E4 | F3: =E3-D3
A4: Deferred | B4: M0021 | C4: PV at flat rate | D4: 63659.718 | E4: =Deferred!E3 | F4: =E4-D4
A5: Deferred | B5: M0021 | C5: IAS 19 PV (curve) | D5: 52122.863 | E5: =Deferred!E4 | F5: =E5-D5
A6: Active | B6: M0013 | C6: PV at flat rate | D6: 311786.16 | E6: =Active!E3 | F6: =E6-D6
A7: Active | B7: M0013 | C7: IAS 19 PV (curve) | D7: 243016.48 | E7: =Active!E4 | F7: =E7-D7
A8: FS_Pensioner | B8: M0017 | C8: FS annuity cost | D8: 293564.85 | E8: =FS_Pensioner!E3 | F8: =E8-D8
A9: FS_Deferred | B9: M0021 | C9: FS transfer value | D9: 43350.927 | E9: =FS_Deferred!E6 | F9: =E9-D9
A10: FS_Active | B10: M0013 | C10: FS transfer value | D10: 134567.79 | E10: =FS_Active!E6 | F10: =E10-D10

Sheet Inputs_IAS19
A1: key | B1: input | C1: value
A2: val_year | B2: Valuation year | C2: 2025
A3: pi | B3: Inflation | C3: 0.018675889
A4: g | B4: Salary growth | C4: 0.028675889
A5: r | B5: Deferred revaluation (future years) | C5: 0.018675889
A6: e | B6: Pension increase (future years) | C6: 0.018675889
A7: known_year | B7: Year of the known increase (0 = none) | C7: 2026
A8: known_inc | B8: Known increase that year | C8: 0.022
A9: spc1 | B9: SPC in year 1 (annual) | C9: 15563.6
A10: offset | B10: SPC offset multiple | C10: 1.5
A11: accrual | B11: Accrual fraction (1/..) | C11: 60
A12: max_service | B12: Maximum service | C12: 40
A13: pre_M | B13: Mortality multiplier before 65, M | C13: 0.66
... A26: flat | B26: Flat discount rate (engine check) | C26: 0.0375

Sheet Inputs_S34
A1: key | B1: input | C1: value
A2: val_year | B2: Valuation year | C2: 2025
A3: pi | B3: Inflation | C3: 0.015
A4: g | B4: Salary growth | C4: 0
A5: r | B5: Deferred revaluation (future years) | C5: 0.015
A6: e | B6: Pension increase (future years) | C6: 0.015
A7: known_year | B7: Year of the known increase (0 = none) | C7: 0
A8: known_inc | B8: Known increase that year | C8: 0
A9: spc1 | B9: SPC in year 1 (annual) | C9: 15563.6
A10: offset | B10: SPC offset multiple | C10: 1.5
A11: accrual | B11: Accrual fraction (1/..) | C11: 60
A12: max_service | B12: Maximum service | C12: 40
A13: pre_M | B13: Mortality multiplier before 65, M | C13: 0.73
... A30: mva_npa | B30: MVA at NPA, index-linked (Nov 2025) | C30: 1.2370036

Sheet Inputs_Annuity
A1: key | B1: input | C1: value
A2: val_year | B2: Valuation year | C2: 2025
A3: pi | B3: Inflation | C3: 0.019
A4: g | B4: Salary growth | C4: 0
A5: r | B5: Deferred revaluation (future years) | C5: 0
A6: e | B6: Pension increase (future years) | C6: 0.0178
A7: known_year | B7: Year of the known increase (0 = none) | C7: 2026
A8: known_inc | B8: Known increase that year | C8: 0.022
A9: spc1 | B9: SPC in year 1 (annual) | C9: 15563.6
A10: offset | B10: SPC offset multiple | C10: 1.5
A11: accrual | B11: Accrual fraction (1/..) | C11: 60
A12: max_service | B12: Maximum service | C12: 40
A13: pre_M | B13: Mortality multiplier before 65, M | C13: 0.62
... A25: load_base | B25: Loading base year | C25: 2014

Sheet ILT
A1: age | B1: q_M (ILT15, extended to 120) | C1: q_F
A2: 0 | B2: 0.00404 | C2: 0.00358
A3: 1 | B3: 0.00029 | C3: 0.00039
A4: 2 | B4: 0.00026 | C4: 0.00021
A5: 3 | B5: 0.00014 | C5: 0.00017
A6: 4 | B6: 0.00016 | C6: 0.00013
A7: 5 | B7: 0.00011 | C7: 7e-05
A8: 6 | B8: 8e-05 | C8: 7e-05
A9: 7 | B9: 0.00015 | C9: 7e-05
A10: 8 | B10: 0.00012 | C10: 7e-05
A11: 9 | B11: 0.0001 | C11: 8e-05
A12: 10 | B12: 8e-05 | C12: 9e-05
A13: 11 | B13: 8e-05 | C13: 0.00011
... A122: 120 | B122: 1 | C122: 1

Sheet Revaluation
A1: revaluation year | B1: official %
A2: 1996 | B2: 1.6
A3: 1997 | B3: 1.5
A4: 1998 | B4: 2.4
A5: 1999 | B5: 1.6
A6: 2000 | B6: 4
A7: 2001 | B7: 4
A8: 2002 | B8: 4
A9: 2003 | B9: 3.5
A10: 2004 | B10: 2.2
A11: 2005 | B11: 2.5
A12: 2006 | B12: 4
A13: 2007 | B13: 4
... A31: 2025 | B31: 2.2

Sheet Curve_IAS19
A1: t | B1: payment time | C1: AAA spot (annual) at payment time | D1: discount factor (AAA + spread) | F1: spread | G1: 0.01
A2: 1 | B2: 0.5 | C2: 0.020129285 | D2: =(1+C2+$G$1)^-B2 | F2: AAA spot 29y | G2: 0.03547617
A3: 2 | B3: 1.5 | C3: 0.020843029 | D3: =(1+C3+$G$1)^-B3 | F3: AAA spot 30y | G3: 0.035398398
A4: 3 | B4: 2.5 | C4: 0.0218221 | D4: =(1+C4+$G$1)^-B4 | F4: DF 29y | G4: =(1+G2+G1)^-29
A5: 4 | B5: 3.5 | C5: 0.022941186 | D5: =(1+C5+$G$1)^-B5 | F5: DF 30y | G5: =(1+G3+G1)^-30
A6: 5 | B6: 4.5 | C6: 0.024116689 | D6: =(1+C6+$G$1)^-B6 | F6: forward 29-30y | G6: =G4/G5-1
A7: 6 | B7: 5.5 | C7: 0.025293537 | D7: =(1+C7+$G$1)^-B7
A8: 7 | B8: 6.5 | C8: 0.026436171 | D8: =(1+C8+$G$1)^-B8
A9: 8 | B9: 7.5 | C9: 0.027522364 | D9: =(1+C9+$G$1)^-B9
A10: 9 | B10: 8.5 | C10: 0.028538976 | D10: =(1+C10+$G$1)^-B10
A11: 10 | B11: 9.5 | C11: 0.029479027 | D11: =(1+C11+$G$1)^-B11
A12: 11 | B12: 10.5 | C12: 0.030339689 | D12: =(1+C12+$G$1)^-B12
A13: 12 | B13: 11.5 | C13: 0.031120892 | D13: =(1+C13+$G$1)^-B13
A14: 13 | B14: 12.5 | C14: 0.031824373 | D14: =(1+C14+$G$1)^-B14
A15: 14 | B15: 13.5 | C15: 0.032453014 | D15: =(1+C15+$G$1)^-B15
A16: 15 | B16: 14.5 | C16: 0.033010391 | D16: =(1+C16+$G$1)^-B16
A17: 16 | B17: 15.5 | C17: 0.033500467 | D17: =(1+C17+$G$1)^-B17
A18: 17 | B18: 16.5 | C18: 0.03392738 | D18: =(1+C18+$G$1)^-B18
... A31: 30 | B31: 29.5 | C31: 0.035439682 | D31: =(1+C31+$G$1)^-B31
A32: 31 | B32: 30.5 | D32: =$G$5*(1+$G$6)^-(B32-30)
A33: 32 | B33: 31.5 | D33: =$G$5*(1+$G$6)^-(B33-30)
A34: 33 | B34: 32.5 | D34: =$G$5*(1+$G$6)^-(B34-30)
A35: 34 | B35: 33.5 | D35: =$G$5*(1+$G$6)^-(B35-30)
A36: 35 | B36: 34.5 | D36: =$G$5*(1+$G$6)^-(B36-30)
A37: 36 | B37: 35.5 | D37: =$G$5*(1+$G$6)^-(B37-30)
A38: 37 | B38: 36.5 | D38: =$G$5*(1+$G$6)^-(B38-30)
A39: 38 | B39: 37.5 | D39: =$G$5*(1+$G$6)^-(B39-30)
A40: 39 | B40: 38.5 | D40: =$G$5*(1+$G$6)^-(B40-30)
A41: 40 | B41: 39.5 | D41: =$G$5*(1+$G$6)^-(B41-30)
A42: 41 | B42: 40.5 | D42: =$G$5*(1+$G$6)^-(B42-30)
A43: 42 | B43: 41.5 | D43: =$G$5*(1+$G$6)^-(B43-30)
... A101: 100 | B101: 99.5 | D101: =$G$5*(1+$G$6)^-(B101-30)

Sheet Curve_Annuity
A1: t | B1: payment time | C1: AAA spot (annual) at payment time | D1: discount factor (AAA + spread) | F1: spread | G1: 0.005
A2: 1 | B2: 0.5 | C2: 0.020129285 | D2: =(1+C2+$G$1)^-B2 | F2: AAA spot 29y | G2: 0.03547617
A3: 2 | B3: 1.5 | C3: 0.020843029 | D3: =(1+C3+$G$1)^-B3 | F3: AAA spot 30y | G3: 0.035398398
A4: 3 | B4: 2.5 | C4: 0.0218221 | D4: =(1+C4+$G$1)^-B4 | F4: DF 29y | G4: =(1+G2+G1)^-29
A5: 4 | B5: 3.5 | C5: 0.022941186 | D5: =(1+C5+$G$1)^-B5 | F5: DF 30y | G5: =(1+G3+G1)^-30
A6: 5 | B6: 4.5 | C6: 0.024116689 | D6: =(1+C6+$G$1)^-B6 | F6: forward 29-30y | G6: =G4/G5-1
A7: 6 | B7: 5.5 | C7: 0.025293537 | D7: =(1+C7+$G$1)^-B7
A8: 7 | B8: 6.5 | C8: 0.026436171 | D8: =(1+C8+$G$1)^-B8
A9: 8 | B9: 7.5 | C9: 0.027522364 | D9: =(1+C9+$G$1)^-B9
A10: 9 | B10: 8.5 | C10: 0.028538976 | D10: =(1+C10+$G$1)^-B10
A11: 10 | B11: 9.5 | C11: 0.029479027 | D11: =(1+C11+$G$1)^-B11
A12: 11 | B12: 10.5 | C12: 0.030339689 | D12: =(1+C12+$G$1)^-B12
A13: 12 | B13: 11.5 | C13: 0.031120892 | D13: =(1+C13+$G$1)^-B13
A14: 13 | B14: 12.5 | C14: 0.031824373 | D14: =(1+C14+$G$1)^-B14
A15: 14 | B15: 13.5 | C15: 0.032453014 | D15: =(1+C15+$G$1)^-B15
A16: 15 | B16: 14.5 | C16: 0.033010391 | D16: =(1+C16+$G$1)^-B16
A17: 16 | B17: 15.5 | C17: 0.033500467 | D17: =(1+C17+$G$1)^-B17
A18: 17 | B18: 16.5 | C18: 0.03392738 | D18: =(1+C18+$G$1)^-B18
... A31: 30 | B31: 29.5 | C31: 0.035439682 | D31: =(1+C31+$G$1)^-B31
A32: 31 | B32: 30.5 | D32: =$G$5*(1+$G$6)^-(B32-30)
A33: 32 | B33: 31.5 | D33: =$G$5*(1+$G$6)^-(B33-30)
A34: 33 | B34: 32.5 | D34: =$G$5*(1+$G$6)^-(B34-30)
A35: 34 | B35: 33.5 | D35: =$G$5*(1+$G$6)^-(B35-30)
A36: 35 | B36: 34.5 | D36: =$G$5*(1+$G$6)^-(B36-30)
A37: 36 | B37: 35.5 | D37: =$G$5*(1+$G$6)^-(B37-30)
A38: 37 | B38: 36.5 | D38: =$G$5*(1+$G$6)^-(B38-30)
A39: 38 | B39: 37.5 | D39: =$G$5*(1+$G$6)^-(B39-30)
A40: 39 | B40: 38.5 | D40: =$G$5*(1+$G$6)^-(B40-30)
A41: 40 | B41: 39.5 | D41: =$G$5*(1+$G$6)^-(B41-30)
A42: 41 | B42: 40.5 | D42: =$G$5*(1+$G$6)^-(B42-30)
A43: 42 | B43: 41.5 | D43: =$G$5*(1+$G$6)^-(B43-30)
... A101: 100 | B101: 99.5 | D101: =$G$5*(1+$G$6)^-(B101-30)

Sheet Pensioner
A1: Pensioner: P x increases x average survival, paid mid-year
A3: member_id | B3: M0017 | D3: PV (flat rate) | E3: =SUM(J19:J118)
A4: sex | B4: M | D4: PV (IAS 19 curve) | E4: =SUM(K19:K118)
A5: age x (nearest, at valuation) | B5: 72
A6: T (years to 65) | B6: 0
A7: pension in payment (2025) | B7: 20331.03
A17: t | B17: year | C17: age | D17: q | E17: survival | F17: avg survival | G17: pension index | H17: cash flow | I17: DF 1 | J17: PV 1 | K17: PV 2
A18: 0 | E18: 1 | G18: 1
A19: 1 | B19: =Inputs_IAS19!$C$2+A19 | C19: =$B$5+A19-1 | D19: =IF(C19>=120,1,MIN(1,IF(A19<=$B$6,IF($B$4="M",Inputs_IAS19!$C$13,Inputs_IAS19!$C$14),IF($B$4="M",Inputs_IAS19!$C$15,Inputs_IAS19!$C$16))*INDEX(ILT!$B$2:$C$122,MIN(C19,120)+1,IF($B$4="M",1,2))*(1-Inputs_IAS19!$C$17)^MAX(B19-Inputs_IAS19!$C$18,0))) | E19: =E18*(1-D19) | F19: =(E18+E19)/2 | G19: =G18*(1+IF(B19=Inputs_IAS19!$C$7,Inputs_IAS19!$C$8,Inputs_IAS19!$C$6)) | H19: =$B$7*G19*F19 | I19: =(1+Inputs_IAS19!$C$26)^-(A19-0.5) | J19: =H19*I19 | K19: =H19*INDEX(Curve_IAS19!$D$2:$D$101,A19)
A20: 2 | B20: =Inputs_IAS19!$C$2+A20 | C20: =$B$5+A20-1 | D20: =IF(C20>=120,1,MIN(1,IF(A20<=$B$6,IF($B$4="M",Inputs_IAS19!$C$13,Inputs_IAS19!$C$14),IF($B$4="M",Inputs_IAS19!$C$15,Inputs_IAS19!$C$16))*INDEX(ILT!$B$2:$C$122,MIN(C20,120)+1,IF($B$4="M",1,2))*(1-Inputs_IAS19!$C$17)^MAX(B20-Inputs_IAS19!$C$18,0))) | E20: =E19*(1-D20) | F20: =(E19+E20)/2 | G20: =G19*(1+IF(B20=Inputs_IAS19!$C$7,Inputs_IAS19!$C$8,Inputs_IAS19!$C$6)) | H20: =$B$7*G20*F20 | I20: =(1+Inputs_IAS19!$C$26)^-(A20-0.5) | J20: =H20*I20 | K20: =H20*INDEX(Curve_IAS19!$D$2:$D$101,A20)
A21: 3 | B21: =Inputs_IAS19!$C$2+A21 | C21: =$B$5+A21-1 | D21: =IF(C21>=120,1,MIN(1,IF(A21<=$B$6,IF($B$4="M",Inputs_IAS19!$C$13,Inputs_IAS19!$C$14),IF($B$4="M",Inputs_IAS19!$C$15,Inputs_IAS19!$C$16))*INDEX(ILT!$B$2:$C$122,MIN(C21,120)+1,IF($B$4="M",1,2))*(1-Inputs_IAS19!$C$17)^MAX(B21-Inputs_IAS19!$C$18,0))) | E21: =E20*(1-D21) | F21: =(E20+E21)/2 | G21: =G20*(1+IF(B21=Inputs_IAS19!$C$7,Inputs_IAS19!$C$8,Inputs_IAS19!$C$6)) | H21: =$B$7*G21*F21 | I21: =(1+Inputs_IAS19!$C$26)^-(A21-0.5) | J21: =H21*I21 | K21: =H21*INDEX(Curve_IAS19!$D$2:$D$101,A21)
A22: 4 | B22: =Inputs_IAS19!$C$2+A22 | C22: =$B$5+A22-1 | D22: =IF(C22>=120,1,MIN(1,IF(A22<=$B$6,IF($B$4="M",Inputs_IAS19!$C$13,Inputs_IAS19!$C$14),IF($B$4="M",Inputs_IAS19!$C$15,Inputs_IAS19!$C$16))*INDEX(ILT!$B$2:$C$122,MIN(C22,120)+1,IF($B$4="M",1,2))*(1-Inputs_IAS19!$C$17)^MAX(B22-Inputs_IAS19!$C$18,0))) | E22: =E21*(1-D22) | F22: =(E21+E22)/2 | G22: =G21*(1+IF(B22=Inputs_IAS19!$C$7,Inputs_IAS19!$C$8,Inputs_IAS19!$C$6)) | H22: =$B$7*G22*F22 | I22: =(1+Inputs_IAS19!$C$26)^-(A22-0.5) | J22: =H22*I22 | K22: =H22*INDEX(Curve_IAS19!$D$2:$D$101,A22)
A23: 5 | B23: =Inputs_IAS19!$C$2+A23 | C23: =$B$5+A23-1 | D23: =IF(C23>=120,1,MIN(1,IF(A23<=$B$6,IF($B$4="M",Inputs_IAS19!$C$13,Inputs_IAS19!$C$14),IF($B$4="M",Inputs_IAS19!$C$15,Inputs_IAS19!$C$16))*INDEX(ILT!$B$2:$C$122,MIN(C23,120)+1,IF($B$4="M",1,2))*(1-Inputs_IAS19!$C$17)^MAX(B23-Inputs_IAS19!$C$18,0))) | E23: =E22*(1-D23) | F23: =(E22+E23)/2 | G23: =G22*(1+IF(B23=Inputs_IAS19!$C$7,Inputs_IAS19!$C$8,Inputs_IAS19!$C$6)) | H23: =$B$7*G23*F23 | I23: =(1+Inputs_IAS19!$C$26)^-(A23-0.5) | J23: =H23*I23 | K23: =H23*INDEX(Curve_IAS19!$D$2:$D$101,A23)
A24: 6 | B24: =Inputs_IAS19!$C$2+A24 | C24: =$B$5+A24-1 | D24: =IF(C24>=120,1,MIN(1,IF(A24<=$B$6,IF($B$4="M",Inputs_IAS19!$C$13,Inputs_IAS19!$C$14),IF($B$4="M",Inputs_IAS19!$C$15,Inputs_IAS19!$C$16))*INDEX(ILT!$B$2:$C$122,MIN(C24,120)+1,IF($B$4="M",1,2))*(1-Inputs_IAS19!$C$17)^MAX(B24-Inputs_IAS19!$C$18,0))) | E24: =E23*(1-D24) | F24: =(E23+E24)/2 | G24: =G23*(1+IF(B24=Inputs_IAS19!$C$7,Inputs_IAS19!$C$8,Inputs_IAS19!$C$6)) | H24: =$B$7*G24*F24 | I24: =(1+Inputs_IAS19!$C$26)^-(A24-0.5) | J24: =H24*I24 | K24: =H24*INDEX(Curve_IAS19!$D$2:$D$101,A24)
A25: 7 | B25: =Inputs_IAS19!$C$2+A25 | C25: =$B$5+A25-1 | D25: =IF(C25>=120,1,MIN(1,IF(A25<=$B$6,IF($B$4="M",Inputs_IAS19!$C$13,Inputs_IAS19!$C$14),IF($B$4="M",Inputs_IAS19!$C$15,Inputs_IAS19!$C$16))*INDEX(ILT!$B$2:$C$122,MIN(C25,120)+1,IF($B$4="M",1,2))*(1-Inputs_IAS19!$C$17)^MAX(B25-Inputs_IAS19!$C$18,0))) | E25: =E24*(1-D25) | F25: =(E24+E25)/2 | G25: =G24*(1+IF(B25=Inputs_IAS19!$C$7,Inputs_IAS19!$C$8,Inputs_IAS19!$C$6)) | H25: =$B$7*G25*F25 | I25: =(1+Inputs_IAS19!$C$26)^-(A25-0.5) | J25: =H25*I25 | K25: =H25*INDEX(Curve_IAS19!$D$2:$D$101,A25)
A26: 8 | B26: =Inputs_IAS19!$C$2+A26 | C26: =$B$5+A26-1 | D26: =IF(C26>=120,1,MIN(1,IF(A26<=$B$6,IF($B$4="M",Inputs_IAS19!$C$13,Inputs_IAS19!$C$14),IF($B$4="M",Inputs_IAS19!$C$15,Inputs_IAS19!$C$16))*INDEX(ILT!$B$2:$C$122,MIN(C26,120)+1,IF($B$4="M",1,2))*(1-Inputs_IAS19!$C$17)^MAX(B26-Inputs_IAS19!$C$18,0))) | E26: =E25*(1-D26) | F26: =(E25+E26)/2 | G26: =G25*(1+IF(B26=Inputs_IAS19!$C$7,Inputs_IAS19!$C$8,Inputs_IAS19!$C$6)) | H26: =$B$7*G26*F26 | I26: =(1+Inputs_IAS19!$C$26)^-(A26-0.5) | J26: =H26*I26 | K26: =H26*INDEX(Curve_IAS19!$D$2:$D$101,A26)
A27: 9 | B27: =Inputs_IAS19!$C$2+A27 | C27: =$B$5+A27-1 | D27: =IF(C27>=120,1,MIN(1,IF(A27<=$B$6,IF($B$4="M",Inputs_IAS19!$C$13,Inputs_IAS19!$C$14),IF($B$4="M",Inputs_IAS19!$C$15,Inputs_IAS19!$C$16))*INDEX(ILT!$B$2:$C$122,MIN(C27,120)+1,IF($B$4="M",1,2))*(1-Inputs_IAS19!$C$17)^MAX(B27-Inputs_IAS19!$C$18,0))) | E27: =E26*(1-D27) | F27: =(E26+E27)/2 | G27: =G26*(1+IF(B27=Inputs_IAS19!$C$7,Inputs_IAS19!$C$8,Inputs_IAS19!$C$6)) | H27: =$B$7*G27*F27 | I27: =(1+Inputs_IAS19!$C$26)^-(A27-0.5) | J27: =H27*I27 | K27: =H27*INDEX(Curve_IAS19!$D$2:$D$101,A27)
A28: 10 | B28: =Inputs_IAS19!$C$2+A28 | C28: =$B$5+A28-1 | D28: =IF(C28>=120,1,MIN(1,IF(A28<=$B$6,IF($B$4="M",Inputs_IAS19!$C$13,Inputs_IAS19!$C$14),IF($B$4="M",Inputs_IAS19!$C$15,Inputs_IAS19!$C$16))*INDEX(ILT!$B$2:$C$122,MIN(C28,120)+1,IF($B$4="M",1,2))*(1-Inputs_IAS19!$C$17)^MAX(B28-Inputs_IAS19!$C$18,0))) | E28: =E27*(1-D28) | F28: =(E27+E28)/2 | G28: =G27*(1+IF(B28=Inputs_IAS19!$C$7,Inputs_IAS19!$C$8,Inputs_IAS19!$C$6)) | H28: =$B$7*G28*F28 | I28: =(1+Inputs_IAS19!$C$26)^-(A28-0.5) | J28: =H28*I28 | K28: =H28*INDEX(Curve_IAS19!$D$2:$D$101,A28)
A29: 11 | B29: =Inputs_IAS19!$C$2+A29 | C29: =$B$5+A29-1 | D29: =IF(C29>=120,1,MIN(1,IF(A29<=$B$6,IF($B$4="M",Inputs_IAS19!$C$13,Inputs_IAS19!$C$14),IF($B$4="M",Inputs_IAS19!$C$15,Inputs_IAS19!$C$16))*INDEX(ILT!$B$2:$C$122,MIN(C29,120)+1,IF($B$4="M",1,2))*(1-Inputs_IAS19!$C$17)^MAX(B29-Inputs_IAS19!$C$18,0))) | E29: =E28*(1-D29) | F29: =(E28+E29)/2 | G29: =G28*(1+IF(B29=Inputs_IAS19!$C$7,Inputs_IAS19!$C$8,Inputs_IAS19!$C$6)) | H29: =$B$7*G29*F29 | I29: =(1+Inputs_IAS19!$C$26)^-(A29-0.5) | J29: =H29*I29 | K29: =H29*INDEX(Curve_IAS19!$D$2:$D$101,A29)
A30: 12 | B30: =Inputs_IAS19!$C$2+A30 | C30: =$B$5+A30-1 | D30: =IF(C30>=120,1,MIN(1,IF(A30<=$B$6,IF($B$4="M",Inputs_IAS19!$C$13,Inputs_IAS19!$C$14),IF($B$4="M",Inputs_IAS19!$C$15,Inputs_IAS19!$C$16))*INDEX(ILT!$B$2:$C$122,MIN(C30,120)+1,IF($B$4="M",1,2))*(1-Inputs_IAS19!$C$17)^MAX(B30-Inputs_IAS19!$C$18,0))) | E30: =E29*(1-D30) | F30: =(E29+E30)/2 | G30: =G29*(1+IF(B30=Inputs_IAS19!$C$7,Inputs_IAS19!$C$8,Inputs_IAS19!$C$6)) | H30: =$B$7*G30*F30 | I30: =(1+Inputs_IAS19!$C$26)^-(A30-0.5) | J30: =H30*I30 | K30: =H30*INDEX(Curve_IAS19!$D$2:$D$101,A30)
... A118: 100 | B118: =Inputs_IAS19!$C$2+A118 | C118: =$B$5+A118-1 | D118: =IF(C118>=120,1,MIN(1,IF(A118<=$B$6,IF($B$4="M",Inputs_IAS19!$C$13,Inputs_IAS19!$C$14),IF($B$4="M",Inputs_IAS19!$C$15,Inputs_IAS19!$C$16))*INDEX(ILT!$B$2:$C$122,MIN(C118,120)+1,IF($B$4="M",1,2))*(1-Inputs_IAS19!$C$17)^MAX(B118-Inputs_IAS19!$C$18,0))) | E118: =E117*(1-D118) | F118: =(E117+E118)/2 | G118: =G117*(1+IF(B118=Inputs_IAS19!$C$7,Inputs_IAS19!$C$8,Inputs_IAS19!$C$6)) | H118: =$B$7*G118*F118 | I118: =(1+Inputs_IAS19!$C$26)^-(A118-0.5) | J118: =H118*I118 | K118: =H118*INDEX(Curve_IAS19!$D$2:$D$101,A118)

Sheet Deferred
A1: Deferred: pension at exit, official revaluation to the valuation year, then r a year to 65
A3: member_id | B3: M0021 | D3: PV (flat rate) | E3: =SUM(J19:J118)
A4: sex | B4: F | D4: PV (IAS 19 curve) | E4: =SUM(K19:K118)
A5: age x (nearest, at valuation) | B5: 50
A6: T (years to 65) | B6: 15
A7: pension at exit | B7: 3866.4
A8: exit year | B8: 2020
A9: exit month | B9: 7
A10: exit day | B10: 20
A11: complete months to 31 Dec | B11: =12-B9+IF(B10=1,1,0)
A12: revaluation factor to valuation year | B12: =N22
A13: pension at valuation date | B13: =B7*B12
A14: pension at 65 x loading | B14: =B13*(1+Inputs_IAS19!$C$5)^B6*(1+IF($B$4="M",Inputs_IAS19!$C$23,Inputs_IAS19!$C$24))^MAX(Inputs_IAS19!$C$2+$B$6-Inputs_IAS19!$C$25,0)
M16: rev. year | N16: factor
A17: t | B17: year | C17: age | D17: q | E17: survival | F17: avg survival | G17: pension index | H17: cash flow | I17: DF 1 | J17: PV 1 | K17: PV 2 | M17: 2020 | N17: =1+INDEX(Revaluation!$B:$B,M17-1996+2)/100*$B$11/12
A18: 0 | E18: 1 | G18: 0 | M18: 2021 | N18: =N17*(1+INDEX(Revaluation!$B:$B,M18-1996+2)/100)
A19: 1 | B19: =Inputs_IAS19!$C$2+A19 | C19: =$B$5+A19-1 | D19: =IF(C19>=120,1,MIN(1,IF(A19<=$B$6,IF($B$4="M",Inputs_IAS19!$C$13,Inputs_IAS19!$C$14),IF($B$4="M",Inputs_IAS19!$C$15,Inputs_IAS19!$C$16))*INDEX(ILT!$B$2:$C$122,MIN(C19,120)+1,IF($B$4="M",1,2))*(1-Inputs_IAS19!$C$17)^MAX(B19-Inputs_IAS19!$C$18,0))) | E19: =E18*(1-D19) | F19: =(E18+E19)/2 | G19: =IF(A19<$B$6+1,0,IF(A19=$B$6+1,1,G18*(1+IF(B19=Inputs_IAS19!$C$7,Inputs_IAS19!$C$8,Inputs_IAS19!$C$6)))) | H19: =$B$14*G19*F19 | I19: =(1+Inputs_IAS19!$C$26)^-(A19-0.5) | J19: =H19*I19 | K19: =H19*INDEX(Curve_IAS19!$D$2:$D$101,A19) | M19: 2022 | N19: =N18*(1+INDEX(Revaluation!$B:$B,M19-1996+2)/100)
A20: 2 | B20: =Inputs_IAS19!$C$2+A20 | C20: =$B$5+A20-1 | D20: =IF(C20>=120,1,MIN(1,IF(A20<=$B$6,IF($B$4="M",Inputs_IAS19!$C$13,Inputs_IAS19!$C$14),IF($B$4="M",Inputs_IAS19!$C$15,Inputs_IAS19!$C$16))*INDEX(ILT!$B$2:$C$122,MIN(C20,120)+1,IF($B$4="M",1,2))*(1-Inputs_IAS19!$C$17)^MAX(B20-Inputs_IAS19!$C$18,0))) | E20: =E19*(1-D20) | F20: =(E19+E20)/2 | G20: =IF(A20<$B$6+1,0,IF(A20=$B$6+1,1,G19*(1+IF(B20=Inputs_IAS19!$C$7,Inputs_IAS19!$C$8,Inputs_IAS19!$C$6)))) | H20: =$B$14*G20*F20 | I20: =(1+Inputs_IAS19!$C$26)^-(A20-0.5) | J20: =H20*I20 | K20: =H20*INDEX(Curve_IAS19!$D$2:$D$101,A20) | M20: 2023 | N20: =N19*(1+INDEX(Revaluation!$B:$B,M20-1996+2)/100)
A21: 3 | B21: =Inputs_IAS19!$C$2+A21 | C21: =$B$5+A21-1 | D21: =IF(C21>=120,1,MIN(1,IF(A21<=$B$6,IF($B$4="M",Inputs_IAS19!$C$13,Inputs_IAS19!$C$14),IF($B$4="M",Inputs_IAS19!$C$15,Inputs_IAS19!$C$16))*INDEX(ILT!$B$2:$C$122,MIN(C21,120)+1,IF($B$4="M",1,2))*(1-Inputs_IAS19!$C$17)^MAX(B21-Inputs_IAS19!$C$18,0))) | E21: =E20*(1-D21) | F21: =(E20+E21)/2 | G21: =IF(A21<$B$6+1,0,IF(A21=$B$6+1,1,G20*(1+IF(B21=Inputs_IAS19!$C$7,Inputs_IAS19!$C$8,Inputs_IAS19!$C$6)))) | H21: =$B$14*G21*F21 | I21: =(1+Inputs_IAS19!$C$26)^-(A21-0.5) | J21: =H21*I21 | K21: =H21*INDEX(Curve_IAS19!$D$2:$D$101,A21) | M21: 2024 | N21: =N20*(1+INDEX(Revaluation!$B:$B,M21-1996+2)/100)
A22: 4 | B22: =Inputs_IAS19!$C$2+A22 | C22: =$B$5+A22-1 | D22: =IF(C22>=120,1,MIN(1,IF(A22<=$B$6,IF($B$4="M",Inputs_IAS19!$C$13,Inputs_IAS19!$C$14),IF($B$4="M",Inputs_IAS19!$C$15,Inputs_IAS19!$C$16))*INDEX(ILT!$B$2:$C$122,MIN(C22,120)+1,IF($B$4="M",1,2))*(1-Inputs_IAS19!$C$17)^MAX(B22-Inputs_IAS19!$C$18,0))) | E22: =E21*(1-D22) | F22: =(E21+E22)/2 | G22: =IF(A22<$B$6+1,0,IF(A22=$B$6+1,1,G21*(1+IF(B22=Inputs_IAS19!$C$7,Inputs_IAS19!$C$8,Inputs_IAS19!$C$6)))) | H22: =$B$14*G22*F22 | I22: =(1+Inputs_IAS19!$C$26)^-(A22-0.5) | J22: =H22*I22 | K22: =H22*INDEX(Curve_IAS19!$D$2:$D$101,A22) | M22: 2025 | N22: =N21*(1+INDEX(Revaluation!$B:$B,M22-1996+2)/100)
A23: 5 | B23: =Inputs_IAS19!$C$2+A23 | C23: =$B$5+A23-1 | D23: =IF(C23>=120,1,MIN(1,IF(A23<=$B$6,IF($B$4="M",Inputs_IAS19!$C$13,Inputs_IAS19!$C$14),IF($B$4="M",Inputs_IAS19!$C$15,Inputs_IAS19!$C$16))*INDEX(ILT!$B$2:$C$122,MIN(C23,120)+1,IF($B$4="M",1,2))*(1-Inputs_IAS19!$C$17)^MAX(B23-Inputs_IAS19!$C$18,0))) | E23: =E22*(1-D23) | F23: =(E22+E23)/2 | G23: =IF(A23<$B$6+1,0,IF(A23=$B$6+1,1,G22*(1+IF(B23=Inputs_IAS19!$C$7,Inputs_IAS19!$C$8,Inputs_IAS19!$C$6)))) | H23: =$B$14*G23*F23 | I23: =(1+Inputs_IAS19!$C$26)^-(A23-0.5) | J23: =H23*I23 | K23: =H23*INDEX(Curve_IAS19!$D$2:$D$101,A23)
A24: 6 | B24: =Inputs_IAS19!$C$2+A24 | C24: =$B$5+A24-1 | D24: =IF(C24>=120,1,MIN(1,IF(A24<=$B$6,IF($B$4="M",Inputs_IAS19!$C$13,Inputs_IAS19!$C$14),IF($B$4="M",Inputs_IAS19!$C$15,Inputs_IAS19!$C$16))*INDEX(ILT!$B$2:$C$122,MIN(C24,120)+1,IF($B$4="M",1,2))*(1-Inputs_IAS19!$C$17)^MAX(B24-Inputs_IAS19!$C$18,0))) | E24: =E23*(1-D24) | F24: =(E23+E24)/2 | G24: =IF(A24<$B$6+1,0,IF(A24=$B$6+1,1,G23*(1+IF(B24=Inputs_IAS19!$C$7,Inputs_IAS19!$C$8,Inputs_IAS19!$C$6)))) | H24: =$B$14*G24*F24 | I24: =(1+Inputs_IAS19!$C$26)^-(A24-0.5) | J24: =H24*I24 | K24: =H24*INDEX(Curve_IAS19!$D$2:$D$101,A24)
A25: 7 | B25: =Inputs_IAS19!$C$2+A25 | C25: =$B$5+A25-1 | D25: =IF(C25>=120,1,MIN(1,IF(A25<=$B$6,IF($B$4="M",Inputs_IAS19!$C$13,Inputs_IAS19!$C$14),IF($B$4="M",Inputs_IAS19!$C$15,Inputs_IAS19!$C$16))*INDEX(ILT!$B$2:$C$122,MIN(C25,120)+1,IF($B$4="M",1,2))*(1-Inputs_IAS19!$C$17)^MAX(B25-Inputs_IAS19!$C$18,0))) | E25: =E24*(1-D25) | F25: =(E24+E25)/2 | G25: =IF(A25<$B$6+1,0,IF(A25=$B$6+1,1,G24*(1+IF(B25=Inputs_IAS19!$C$7,Inputs_IAS19!$C$8,Inputs_IAS19!$C$6)))) | H25: =$B$14*G25*F25 | I25: =(1+Inputs_IAS19!$C$26)^-(A25-0.5) | J25: =H25*I25 | K25: =H25*INDEX(Curve_IAS19!$D$2:$D$101,A25)
A26: 8 | B26: =Inputs_IAS19!$C$2+A26 | C26: =$B$5+A26-1 | D26: =IF(C26>=120,1,MIN(1,IF(A26<=$B$6,IF($B$4="M",Inputs_IAS19!$C$13,Inputs_IAS19!$C$14),IF($B$4="M",Inputs_IAS19!$C$15,Inputs_IAS19!$C$16))*INDEX(ILT!$B$2:$C$122,MIN(C26,120)+1,IF($B$4="M",1,2))*(1-Inputs_IAS19!$C$17)^MAX(B26-Inputs_IAS19!$C$18,0))) | E26: =E25*(1-D26) | F26: =(E25+E26)/2 | G26: =IF(A26<$B$6+1,0,IF(A26=$B$6+1,1,G25*(1+IF(B26=Inputs_IAS19!$C$7,Inputs_IAS19!$C$8,Inputs_IAS19!$C$6)))) | H26: =$B$14*G26*F26 | I26: =(1+Inputs_IAS19!$C$26)^-(A26-0.5) | J26: =H26*I26 | K26: =H26*INDEX(Curve_IAS19!$D$2:$D$101,A26)
A27: 9 | B27: =Inputs_IAS19!$C$2+A27 | C27: =$B$5+A27-1 | D27: =IF(C27>=120,1,MIN(1,IF(A27<=$B$6,IF($B$4="M",Inputs_IAS19!$C$13,Inputs_IAS19!$C$14),IF($B$4="M",Inputs_IAS19!$C$15,Inputs_IAS19!$C$16))*INDEX(ILT!$B$2:$C$122,MIN(C27,120)+1,IF($B$4="M",1,2))*(1-Inputs_IAS19!$C$17)^MAX(B27-Inputs_IAS19!$C$18,0))) | E27: =E26*(1-D27) | F27: =(E26+E27)/2 | G27: =IF(A27<$B$6+1,0,IF(A27=$B$6+1,1,G26*(1+IF(B27=Inputs_IAS19!$C$7,Inputs_IAS19!$C$8,Inputs_IAS19!$C$6)))) | H27: =$B$14*G27*F27 | I27: =(1+Inputs_IAS19!$C$26)^-(A27-0.5) | J27: =H27*I27 | K27: =H27*INDEX(Curve_IAS19!$D$2:$D$101,A27)
A28: 10 | B28: =Inputs_IAS19!$C$2+A28 | C28: =$B$5+A28-1 | D28: =IF(C28>=120,1,MIN(1,IF(A28<=$B$6,IF($B$4="M",Inputs_IAS19!$C$13,Inputs_IAS19!$C$14),IF($B$4="M",Inputs_IAS19!$C$15,Inputs_IAS19!$C$16))*INDEX(ILT!$B$2:$C$122,MIN(C28,120)+1,IF($B$4="M",1,2))*(1-Inputs_IAS19!$C$17)^MAX(B28-Inputs_IAS19!$C$18,0))) | E28: =E27*(1-D28) | F28: =(E27+E28)/2 | G28: =IF(A28<$B$6+1,0,IF(A28=$B$6+1,1,G27*(1+IF(B28=Inputs_IAS19!$C$7,Inputs_IAS19!$C$8,Inputs_IAS19!$C$6)))) | H28: =$B$14*G28*F28 | I28: =(1+Inputs_IAS19!$C$26)^-(A28-0.5) | J28: =H28*I28 | K28: =H28*INDEX(Curve_IAS19!$D$2:$D$101,A28)
A29: 11 | B29: =Inputs_IAS19!$C$2+A29 | C29: =$B$5+A29-1 | D29: =IF(C29>=120,1,MIN(1,IF(A29<=$B$6,IF($B$4="M",Inputs_IAS19!$C$13,Inputs_IAS19!$C$14),IF($B$4="M",Inputs_IAS19!$C$15,Inputs_IAS19!$C$16))*INDEX(ILT!$B$2:$C$122,MIN(C29,120)+1,IF($B$4="M",1,2))*(1-Inputs_IAS19!$C$17)^MAX(B29-Inputs_IAS19!$C$18,0))) | E29: =E28*(1-D29) | F29: =(E28+E29)/2 | G29: =IF(A29<$B$6+1,0,IF(A29=$B$6+1,1,G28*(1+IF(B29=Inputs_IAS19!$C$7,Inputs_IAS19!$C$8,Inputs_IAS19!$C$6)))) | H29: =$B$14*G29*F29 | I29: =(1+Inputs_IAS19!$C$26)^-(A29-0.5) | J29: =H29*I29 | K29: =H29*INDEX(Curve_IAS19!$D$2:$D$101,A29)
A30: 12 | B30: =Inputs_IAS19!$C$2+A30 | C30: =$B$5+A30-1 | D30: =IF(C30>=120,1,MIN(1,IF(A30<=$B$6,IF($B$4="M",Inputs_IAS19!$C$13,Inputs_IAS19!$C$14),IF($B$4="M",Inputs_IAS19!$C$15,Inputs_IAS19!$C$16))*INDEX(ILT!$B$2:$C$122,MIN(C30,120)+1,IF($B$4="M",1,2))*(1-Inputs_IAS19!$C$17)^MAX(B30-Inputs_IAS19!$C$18,0))) | E30: =E29*(1-D30) | F30: =(E29+E30)/2 | G30: =IF(A30<$B$6+1,0,IF(A30=$B$6+1,1,G29*(1+IF(B30=Inputs_IAS19!$C$7,Inputs_IAS19!$C$8,Inputs_IAS19!$C$6)))) | H30: =$B$14*G30*F30 | I30: =(1+Inputs_IAS19!$C$26)^-(A30-0.5) | J30: =H30*I30 | K30: =H30*INDEX(Curve_IAS19!$D$2:$D$101,A30)
A31: 13 | B31: =Inputs_IAS19!$C$2+A31 | C31: =$B$5+A31-1 | D31: =IF(C31>=120,1,MIN(1,IF(A31<=$B$6,IF($B$4="M",Inputs_IAS19!$C$13,Inputs_IAS19!$C$14),IF($B$4="M",Inputs_IAS19!$C$15,Inputs_IAS19!$C$16))*INDEX(ILT!$B$2:$C$122,MIN(C31,120)+1,IF($B$4="M",1,2))*(1-Inputs_IAS19!$C$17)^MAX(B31-Inputs_IAS19!$C$18,0))) | E31: =E30*(1-D31) | F31: =(E30+E31)/2 | G31: =IF(A31<$B$6+1,0,IF(A31=$B$6+1,1,G30*(1+IF(B31=Inputs_IAS19!$C$7,Inputs_IAS19!$C$8,Inputs_IAS19!$C$6)))) | H31: =$B$14*G31*F31 | I31: =(1+Inputs_IAS19!$C$26)^-(A31-0.5) | J31: =H31*I31 | K31: =H31*INDEX(Curve_IAS19!$D$2:$D$101,A31)
A32: 14 | B32: =Inputs_IAS19!$C$2+A32 | C32: =$B$5+A32-1 | D32: =IF(C32>=120,1,MIN(1,IF(A32<=$B$6,IF($B$4="M",Inputs_IAS19!$C$13,Inputs_IAS19!$C$14),IF($B$4="M",Inputs_IAS19!$C$15,Inputs_IAS19!$C$16))*INDEX(ILT!$B$2:$C$122,MIN(C32,120)+1,IF($B$4="M",1,2))*(1-Inputs_IAS19!$C$17)^MAX(B32-Inputs_IAS19!$C$18,0))) | E32: =E31*(1-D32) | F32: =(E31+E32)/2 | G32: =IF(A32<$B$6+1,0,IF(A32=$B$6+1,1,G31*(1+IF(B32=Inputs_IAS19!$C$7,Inputs_IAS19!$C$8,Inputs_IAS19!$C$6)))) | H32: =$B$14*G32*F32 | I32: =(1+Inputs_IAS19!$C$26)^-(A32-0.5) | J32: =H32*I32 | K32: =H32*INDEX(Curve_IAS19!$D$2:$D$101,A32)
A33: 15 | B33: =Inputs_IAS19!$C$2+A33 | C33: =$B$5+A33-1 | D33: =IF(C33>=120,1,MIN(1,IF(A33<=$B$6,IF($B$4="M",Inputs_IAS19!$C$13,Inputs_IAS19!$C$14),IF($B$4="M",Inputs_IAS19!$C$15,Inputs_IAS19!$C$16))*INDEX(ILT!$B$2:$C$122,MIN(C33,120)+1,IF($B$4="M",1,2))*(1-Inputs_IAS19!$C$17)^MAX(B33-Inputs_IAS19!$C$18,0))) | E33: =E32*(1-D33) | F33: =(E32+E33)/2 | G33: =IF(A33<$B$6+1,0,IF(A33=$B$6+1,1,G32*(1+IF(B33=Inputs_IAS19!$C$7,Inputs_IAS19!$C$8,Inputs_IAS19!$C$6)))) | H33: =$B$14*G33*F33 | I33: =(1+Inputs_IAS19!$C$26)^-(A33-0.5) | J33: =H33*I33 | K33: =H33*INDEX(Curve_IAS19!$D$2:$D$101,A33)
A34: 16 | B34: =Inputs_IAS19!$C$2+A34 | C34: =$B$5+A34-1 | D34: =IF(C34>=120,1,MIN(1,IF(A34<=$B$6,IF($B$4="M",Inputs_IAS19!$C$13,Inputs_IAS19!$C$14),IF($B$4="M",Inputs_IAS19!$C$15,Inputs_IAS19!$C$16))*INDEX(ILT!$B$2:$C$122,MIN(C34,120)+1,IF($B$4="M",1,2))*(1-Inputs_IAS19!$C$17)^MAX(B34-Inputs_IAS19!$C$18,0))) | E34: =E33*(1-D34) | F34: =(E33+E34)/2 | G34: =IF(A34<$B$6+1,0,IF(A34=$B$6+1,1,G33*(1+IF(B34=Inputs_IAS19!$C$7,Inputs_IAS19!$C$8,Inputs_IAS19!$C$6)))) | H34: =$B$14*G34*F34 | I34: =(1+Inputs_IAS19!$C$26)^-(A34-0.5) | J34: =H34*I34 | K34: =H34*INDEX(Curve_IAS19!$D$2:$D$101,A34)
... A118: 100 | B118: =Inputs_IAS19!$C$2+A118 | C118: =$B$5+A118-1 | D118: =IF(C118>=120,1,MIN(1,IF(A118<=$B$6,IF($B$4="M",Inputs_IAS19!$C$13,Inputs_IAS19!$C$14),IF($B$4="M",Inputs_IAS19!$C$15,Inputs_IAS19!$C$16))*INDEX(ILT!$B$2:$C$122,MIN(C118,120)+1,IF($B$4="M",1,2))*(1-Inputs_IAS19!$C$17)^MAX(B118-Inputs_IAS19!$C$18,0))) | E118: =E117*(1-D118) | F118: =(E117+E118)/2 | G118: =IF(A118<$B$6+1,0,IF(A118=$B$6+1,1,G117*(1+IF(B118=Inputs_IAS19!$C$7,Inputs_IAS19!$C$8,Inputs_IAS19!$C$6)))) | H118: =$B$14*G118*F118 | I118: =(1+Inputs_IAS19!$C$26)^-(A118-0.5) | J118: =H118*I118 | K118: =H118*INDEX(Curve_IAS19!$D$2:$D$101,A118)

Sheet Active
A1: Active: withdraw (deferred pension) / die (nothing) / retire at 65; past service only (PUC)
A3: member_id | B3: M0013 | D3: PV (flat rate) | E3: =SUM(J19:J118)
A4: sex | B4: M | D4: PV (IAS 19 curve) | E4: =SUM(K19:K118)
A5: age x (nearest, at valuation) | B5: 43
A6: T (years to 65) | B6: 22
A7: service n (years) | B7: 21.2485
A8: salary (2025) | B8: 81469
A9: salary at 65 | B9: =B8*(1+Inputs_IAS19!$C$4)^B6
A10: SPC at 65 | B10: =Inputs_IAS19!$C$9*(1+Inputs_IAS19!$C$3)^(B6-1)
A11: retirement pension R | B11: =MIN(B7,Inputs_IAS19!$C$12)/Inputs_IAS19!$C$11*MAX(B9-Inputs_IAS19!$C$10*B10,0)
A12: K = leaver terms + in service at 65 x R / s(T) | B12: =SUM(U19:U118)+INDEX(O18:O118,$B$6+1)*B11/INDEX(E18:E118,$B$6+1)
A17: t | B17: year | C17: age | D17: q | E17: survival | F17: avg survival | G17: pension index | H17: cash flow | I17: DF 1 | J17: PV 1 | K17: PV 2 | M17: q death | N17: q withdraw | O17: in service | P17: leavers | Q17: salary | R17: SPC | S17: B at exit | T17: B65 | U17: leaver term
A18: 0 | E18: 1 | G18: 0 | O18: 1
A19: 1 | B19: =Inputs_IAS19!$C$2+A19 | C19: =$B$5+A19-1 | D19: =IF(C19>=120,1,MIN(1,IF(A19<=$B$6,IF($B$4="M",Inputs_IAS19!$C$13,Inputs_IAS19!$C$14),IF($B$4="M",Inputs_IAS19!$C$15,Inputs_IAS19!$C$16))*INDEX(ILT!$B$2:$C$122,MIN(C19,120)+1,IF($B$4="M",1,2))*(1-Inputs_IAS19!$C$17)^MAX(B19-Inputs_IAS19!$C$18,0))) | E19: =E18*(1-D19) | F19: =(E18+E19)/2 | G19: =IF(A19<$B$6+1,0,IF(A19=$B$6+1,1,G18*(1+IF(B19=Inputs_IAS19!$C$7,Inputs_IAS19!$C$8,Inputs_IAS19!$C$6)))) | H19: =$B$12*G19*F19 | I19: =(1+Inputs_IAS19!$C$26)^-(A19-0.5) | J19: =H19*I19 | K19: =H19*INDEX(Curve_IAS19!$D$2:$D$101,A19) | M19: =IF(A19<=$B$6,1-E19/E18,0) | N19: =IF(A19<=$B$6,Inputs_IAS19!$C$19*IF(C19<Inputs_IAS19!$C$22,MAX(0,Inputs_IAS19!$C$20-Inputs_IAS19!$C$21*(C19-35)),0),0) | O19: =O18*(1-M19-N19) | P19: =O18*N19 | Q19: =$B$8*(1+Inputs_IAS19!$C$4)^A19 | R19: =Inputs_IAS19!$C$9*(1+Inputs_IAS19!$C$3)^(A19-1) | S19: =MIN($B$7,Inputs_IAS19!$C$12)/Inputs_IAS19!$C$11*MAX(Q19-Inputs_IAS19!$C$10*R19,0) | T19: =S19*(1+Inputs_IAS19!$C$5*0.5)*(1+Inputs_IAS19!$C$5)^($B$6-A19) | U19: =IF(A19<=$B$6,P19*(1-M19/2)*T19/E19,0)
A20: 2 | B20: =Inputs_IAS19!$C$2+A20 | C20: =$B$5+A20-1 | D20: =IF(C20>=120,1,MIN(1,IF(A20<=$B$6,IF($B$4="M",Inputs_IAS19!$C$13,Inputs_IAS19!$C$14),IF($B$4="M",Inputs_IAS19!$C$15,Inputs_IAS19!$C$16))*INDEX(ILT!$B$2:$C$122,MIN(C20,120)+1,IF($B$4="M",1,2))*(1-Inputs_IAS19!$C$17)^MAX(B20-Inputs_IAS19!$C$18,0))) | E20: =E19*(1-D20) | F20: =(E19+E20)/2 | G20: =IF(A20<$B$6+1,0,IF(A20=$B$6+1,1,G19*(1+IF(B20=Inputs_IAS19!$C$7,Inputs_IAS19!$C$8,Inputs_IAS19!$C$6)))) | H20: =$B$12*G20*F20 | I20: =(1+Inputs_IAS19!$C$26)^-(A20-0.5) | J20: =H20*I20 | K20: =H20*INDEX(Curve_IAS19!$D$2:$D$101,A20) | M20: =IF(A20<=$B$6,1-E20/E19,0) | N20: =IF(A20<=$B$6,Inputs_IAS19!$C$19*IF(C20<Inputs_IAS19!$C$22,MAX(0,Inputs_IAS19!$C$20-Inputs_IAS19!$C$21*(C20-35)),0),0) | O20: =O19*(1-M20-N20) | P20: =O19*N20 | Q20: =$B$8*(1+Inputs_IAS19!$C$4)^A20 | R20: =Inputs_IAS19!$C$9*(1+Inputs_IAS19!$C$3)^(A20-1) | S20: =MIN($B$7,Inputs_IAS19!$C$12)/Inputs_IAS19!$C$11*MAX(Q20-Inputs_IAS19!$C$10*R20,0) | T20: =S20*(1+Inputs_IAS19!$C$5*0.5)*(1+Inputs_IAS19!$C$5)^($B$6-A20) | U20: =IF(A20<=$B$6,P20*(1-M20/2)*T20/E20,0)
A21: 3 | B21: =Inputs_IAS19!$C$2+A21 | C21: =$B$5+A21-1 | D21: =IF(C21>=120,1,MIN(1,IF(A21<=$B$6,IF($B$4="M",Inputs_IAS19!$C$13,Inputs_IAS19!$C$14),IF($B$4="M",Inputs_IAS19!$C$15,Inputs_IAS19!$C$16))*INDEX(ILT!$B$2:$C$122,MIN(C21,120)+1,IF($B$4="M",1,2))*(1-Inputs_IAS19!$C$17)^MAX(B21-Inputs_IAS19!$C$18,0))) | E21: =E20*(1-D21) | F21: =(E20+E21)/2 | G21: =IF(A21<$B$6+1,0,IF(A21=$B$6+1,1,G20*(1+IF(B21=Inputs_IAS19!$C$7,Inputs_IAS19!$C$8,Inputs_IAS19!$C$6)))) | H21: =$B$12*G21*F21 | I21: =(1+Inputs_IAS19!$C$26)^-(A21-0.5) | J21: =H21*I21 | K21: =H21*INDEX(Curve_IAS19!$D$2:$D$101,A21) | M21: =IF(A21<=$B$6,1-E21/E20,0) | N21: =IF(A21<=$B$6,Inputs_IAS19!$C$19*IF(C21<Inputs_IAS19!$C$22,MAX(0,Inputs_IAS19!$C$20-Inputs_IAS19!$C$21*(C21-35)),0),0) | O21: =O20*(1-M21-N21) | P21: =O20*N21 | Q21: =$B$8*(1+Inputs_IAS19!$C$4)^A21 | R21: =Inputs_IAS19!$C$9*(1+Inputs_IAS19!$C$3)^(A21-1) | S21: =MIN($B$7,Inputs_IAS19!$C$12)/Inputs_IAS19!$C$11*MAX(Q21-Inputs_IAS19!$C$10*R21,0) | T21: =S21*(1+Inputs_IAS19!$C$5*0.5)*(1+Inputs_IAS19!$C$5)^($B$6-A21) | U21: =IF(A21<=$B$6,P21*(1-M21/2)*T21/E21,0)
A22: 4 | B22: =Inputs_IAS19!$C$2+A22 | C22: =$B$5+A22-1 | D22: =IF(C22>=120,1,MIN(1,IF(A22<=$B$6,IF($B$4="M",Inputs_IAS19!$C$13,Inputs_IAS19!$C$14),IF($B$4="M",Inputs_IAS19!$C$15,Inputs_IAS19!$C$16))*INDEX(ILT!$B$2:$C$122,MIN(C22,120)+1,IF($B$4="M",1,2))*(1-Inputs_IAS19!$C$17)^MAX(B22-Inputs_IAS19!$C$18,0))) | E22: =E21*(1-D22) | F22: =(E21+E22)/2 | G22: =IF(A22<$B$6+1,0,IF(A22=$B$6+1,1,G21*(1+IF(B22=Inputs_IAS19!$C$7,Inputs_IAS19!$C$8,Inputs_IAS19!$C$6)))) | H22: =$B$12*G22*F22 | I22: =(1+Inputs_IAS19!$C$26)^-(A22-0.5) | J22: =H22*I22 | K22: =H22*INDEX(Curve_IAS19!$D$2:$D$101,A22) | M22: =IF(A22<=$B$6,1-E22/E21,0) | N22: =IF(A22<=$B$6,Inputs_IAS19!$C$19*IF(C22<Inputs_IAS19!$C$22,MAX(0,Inputs_IAS19!$C$20-Inputs_IAS19!$C$21*(C22-35)),0),0) | O22: =O21*(1-M22-N22) | P22: =O21*N22 | Q22: =$B$8*(1+Inputs_IAS19!$C$4)^A22 | R22: =Inputs_IAS19!$C$9*(1+Inputs_IAS19!$C$3)^(A22-1) | S22: =MIN($B$7,Inputs_IAS19!$C$12)/Inputs_IAS19!$C$11*MAX(Q22-Inputs_IAS19!$C$10*R22,0) | T22: =S22*(1+Inputs_IAS19!$C$5*0.5)*(1+Inputs_IAS19!$C$5)^($B$6-A22) | U22: =IF(A22<=$B$6,P22*(1-M22/2)*T22/E22,0)
A23: 5 | B23: =Inputs_IAS19!$C$2+A23 | C23: =$B$5+A23-1 | D23: =IF(C23>=120,1,MIN(1,IF(A23<=$B$6,IF($B$4="M",Inputs_IAS19!$C$13,Inputs_IAS19!$C$14),IF($B$4="M",Inputs_IAS19!$C$15,Inputs_IAS19!$C$16))*INDEX(ILT!$B$2:$C$122,MIN(C23,120)+1,IF($B$4="M",1,2))*(1-Inputs_IAS19!$C$17)^MAX(B23-Inputs_IAS19!$C$18,0))) | E23: =E22*(1-D23) | F23: =(E22+E23)/2 | G23: =IF(A23<$B$6+1,0,IF(A23=$B$6+1,1,G22*(1+IF(B23=Inputs_IAS19!$C$7,Inputs_IAS19!$C$8,Inputs_IAS19!$C$6)))) | H23: =$B$12*G23*F23 | I23: =(1+Inputs_IAS19!$C$26)^-(A23-0.5) | J23: =H23*I23 | K23: =H23*INDEX(Curve_IAS19!$D$2:$D$101,A23) | M23: =IF(A23<=$B$6,1-E23/E22,0) | N23: =IF(A23<=$B$6,Inputs_IAS19!$C$19*IF(C23<Inputs_IAS19!$C$22,MAX(0,Inputs_IAS19!$C$20-Inputs_IAS19!$C$21*(C23-35)),0),0) | O23: =O22*(1-M23-N23) | P23: =O22*N23 | Q23: =$B$8*(1+Inputs_IAS19!$C$4)^A23 | R23: =Inputs_IAS19!$C$9*(1+Inputs_IAS19!$C$3)^(A23-1) | S23: =MIN($B$7,Inputs_IAS19!$C$12)/Inputs_IAS19!$C$11*MAX(Q23-Inputs_IAS19!$C$10*R23,0) | T23: =S23*(1+Inputs_IAS19!$C$5*0.5)*(1+Inputs_IAS19!$C$5)^($B$6-A23) | U23: =IF(A23<=$B$6,P23*(1-M23/2)*T23/E23,0)
A24: 6 | B24: =Inputs_IAS19!$C$2+A24 | C24: =$B$5+A24-1 | D24: =IF(C24>=120,1,MIN(1,IF(A24<=$B$6,IF($B$4="M",Inputs_IAS19!$C$13,Inputs_IAS19!$C$14),IF($B$4="M",Inputs_IAS19!$C$15,Inputs_IAS19!$C$16))*INDEX(ILT!$B$2:$C$122,MIN(C24,120)+1,IF($B$4="M",1,2))*(1-Inputs_IAS19!$C$17)^MAX(B24-Inputs_IAS19!$C$18,0))) | E24: =E23*(1-D24) | F24: =(E23+E24)/2 | G24: =IF(A24<$B$6+1,0,IF(A24=$B$6+1,1,G23*(1+IF(B24=Inputs_IAS19!$C$7,Inputs_IAS19!$C$8,Inputs_IAS19!$C$6)))) | H24: =$B$12*G24*F24 | I24: =(1+Inputs_IAS19!$C$26)^-(A24-0.5) | J24: =H24*I24 | K24: =H24*INDEX(Curve_IAS19!$D$2:$D$101,A24) | M24: =IF(A24<=$B$6,1-E24/E23,0) | N24: =IF(A24<=$B$6,Inputs_IAS19!$C$19*IF(C24<Inputs_IAS19!$C$22,MAX(0,Inputs_IAS19!$C$20-Inputs_IAS19!$C$21*(C24-35)),0),0) | O24: =O23*(1-M24-N24) | P24: =O23*N24 | Q24: =$B$8*(1+Inputs_IAS19!$C$4)^A24 | R24: =Inputs_IAS19!$C$9*(1+Inputs_IAS19!$C$3)^(A24-1) | S24: =MIN($B$7,Inputs_IAS19!$C$12)/Inputs_IAS19!$C$11*MAX(Q24-Inputs_IAS19!$C$10*R24,0) | T24: =S24*(1+Inputs_IAS19!$C$5*0.5)*(1+Inputs_IAS19!$C$5)^($B$6-A24) | U24: =IF(A24<=$B$6,P24*(1-M24/2)*T24/E24,0)
A25: 7 | B25: =Inputs_IAS19!$C$2+A25 | C25: =$B$5+A25-1 | D25: =IF(C25>=120,1,MIN(1,IF(A25<=$B$6,IF($B$4="M",Inputs_IAS19!$C$13,Inputs_IAS19!$C$14),IF($B$4="M",Inputs_IAS19!$C$15,Inputs_IAS19!$C$16))*INDEX(ILT!$B$2:$C$122,MIN(C25,120)+1,IF($B$4="M",1,2))*(1-Inputs_IAS19!$C$17)^MAX(B25-Inputs_IAS19!$C$18,0))) | E25: =E24*(1-D25) | F25: =(E24+E25)/2 | G25: =IF(A25<$B$6+1,0,IF(A25=$B$6+1,1,G24*(1+IF(B25=Inputs_IAS19!$C$7,Inputs_IAS19!$C$8,Inputs_IAS19!$C$6)))) | H25: =$B$12*G25*F25 | I25: =(1+Inputs_IAS19!$C$26)^-(A25-0.5) | J25: =H25*I25 | K25: =H25*INDEX(Curve_IAS19!$D$2:$D$101,A25) | M25: =IF(A25<=$B$6,1-E25/E24,0) | N25: =IF(A25<=$B$6,Inputs_IAS19!$C$19*IF(C25<Inputs_IAS19!$C$22,MAX(0,Inputs_IAS19!$C$20-Inputs_IAS19!$C$21*(C25-35)),0),0) | O25: =O24*(1-M25-N25) | P25: =O24*N25 | Q25: =$B$8*(1+Inputs_IAS19!$C$4)^A25 | R25: =Inputs_IAS19!$C$9*(1+Inputs_IAS19!$C$3)^(A25-1) | S25: =MIN($B$7,Inputs_IAS19!$C$12)/Inputs_IAS19!$C$11*MAX(Q25-Inputs_IAS19!$C$10*R25,0) | T25: =S25*(1+Inputs_IAS19!$C$5*0.5)*(1+Inputs_IAS19!$C$5)^($B$6-A25) | U25: =IF(A25<=$B$6,P25*(1-M25/2)*T25/E25,0)
A26: 8 | B26: =Inputs_IAS19!$C$2+A26 | C26: =$B$5+A26-1 | D26: =IF(C26>=120,1,MIN(1,IF(A26<=$B$6,IF($B$4="M",Inputs_IAS19!$C$13,Inputs_IAS19!$C$14),IF($B$4="M",Inputs_IAS19!$C$15,Inputs_IAS19!$C$16))*INDEX(ILT!$B$2:$C$122,MIN(C26,120)+1,IF($B$4="M",1,2))*(1-Inputs_IAS19!$C$17)^MAX(B26-Inputs_IAS19!$C$18,0))) | E26: =E25*(1-D26) | F26: =(E25+E26)/2 | G26: =IF(A26<$B$6+1,0,IF(A26=$B$6+1,1,G25*(1+IF(B26=Inputs_IAS19!$C$7,Inputs_IAS19!$C$8,Inputs_IAS19!$C$6)))) | H26: =$B$12*G26*F26 | I26: =(1+Inputs_IAS19!$C$26)^-(A26-0.5) | J26: =H26*I26 | K26: =H26*INDEX(Curve_IAS19!$D$2:$D$101,A26) | M26: =IF(A26<=$B$6,1-E26/E25,0) | N26: =IF(A26<=$B$6,Inputs_IAS19!$C$19*IF(C26<Inputs_IAS19!$C$22,MAX(0,Inputs_IAS19!$C$20-Inputs_IAS19!$C$21*(C26-35)),0),0) | O26: =O25*(1-M26-N26) | P26: =O25*N26 | Q26: =$B$8*(1+Inputs_IAS19!$C$4)^A26 | R26: =Inputs_IAS19!$C$9*(1+Inputs_IAS19!$C$3)^(A26-1) | S26: =MIN($B$7,Inputs_IAS19!$C$12)/Inputs_IAS19!$C$11*MAX(Q26-Inputs_IAS19!$C$10*R26,0) | T26: =S26*(1+Inputs_IAS19!$C$5*0.5)*(1+Inputs_IAS19!$C$5)^($B$6-A26) | U26: =IF(A26<=$B$6,P26*(1-M26/2)*T26/E26,0)
A27: 9 | B27: =Inputs_IAS19!$C$2+A27 | C27: =$B$5+A27-1 | D27: =IF(C27>=120,1,MIN(1,IF(A27<=$B$6,IF($B$4="M",Inputs_IAS19!$C$13,Inputs_IAS19!$C$14),IF($B$4="M",Inputs_IAS19!$C$15,Inputs_IAS19!$C$16))*INDEX(ILT!$B$2:$C$122,MIN(C27,120)+1,IF($B$4="M",1,2))*(1-Inputs_IAS19!$C$17)^MAX(B27-Inputs_IAS19!$C$18,0))) | E27: =E26*(1-D27) | F27: =(E26+E27)/2 | G27: =IF(A27<$B$6+1,0,IF(A27=$B$6+1,1,G26*(1+IF(B27=Inputs_IAS19!$C$7,Inputs_IAS19!$C$8,Inputs_IAS19!$C$6)))) | H27: =$B$12*G27*F27 | I27: =(1+Inputs_IAS19!$C$26)^-(A27-0.5) | J27: =H27*I27 | K27: =H27*INDEX(Curve_IAS19!$D$2:$D$101,A27) | M27: =IF(A27<=$B$6,1-E27/E26,0) | N27: =IF(A27<=$B$6,Inputs_IAS19!$C$19*IF(C27<Inputs_IAS19!$C$22,MAX(0,Inputs_IAS19!$C$20-Inputs_IAS19!$C$21*(C27-35)),0),0) | O27: =O26*(1-M27-N27) | P27: =O26*N27 | Q27: =$B$8*(1+Inputs_IAS19!$C$4)^A27 | R27: =Inputs_IAS19!$C$9*(1+Inputs_IAS19!$C$3)^(A27-1) | S27: =MIN($B$7,Inputs_IAS19!$C$12)/Inputs_IAS19!$C$11*MAX(Q27-Inputs_IAS19!$C$10*R27,0) | T27: =S27*(1+Inputs_IAS19!$C$5*0.5)*(1+Inputs_IAS19!$C$5)^($B$6-A27) | U27: =IF(A27<=$B$6,P27*(1-M27/2)*T27/E27,0)
A28: 10 | B28: =Inputs_IAS19!$C$2+A28 | C28: =$B$5+A28-1 | D28: =IF(C28>=120,1,MIN(1,IF(A28<=$B$6,IF($B$4="M",Inputs_IAS19!$C$13,Inputs_IAS19!$C$14),IF($B$4="M",Inputs_IAS19!$C$15,Inputs_IAS19!$C$16))*INDEX(ILT!$B$2:$C$122,MIN(C28,120)+1,IF($B$4="M",1,2))*(1-Inputs_IAS19!$C$17)^MAX(B28-Inputs_IAS19!$C$18,0))) | E28: =E27*(1-D28) | F28: =(E27+E28)/2 | G28: =IF(A28<$B$6+1,0,IF(A28=$B$6+1,1,G27*(1+IF(B28=Inputs_IAS19!$C$7,Inputs_IAS19!$C$8,Inputs_IAS19!$C$6)))) | H28: =$B$12*G28*F28 | I28: =(1+Inputs_IAS19!$C$26)^-(A28-0.5) | J28: =H28*I28 | K28: =H28*INDEX(Curve_IAS19!$D$2:$D$101,A28) | M28: =IF(A28<=$B$6,1-E28/E27,0) | N28: =IF(A28<=$B$6,Inputs_IAS19!$C$19*IF(C28<Inputs_IAS19!$C$22,MAX(0,Inputs_IAS19!$C$20-Inputs_IAS19!$C$21*(C28-35)),0),0) | O28: =O27*(1-M28-N28) | P28: =O27*N28 | Q28: =$B$8*(1+Inputs_IAS19!$C$4)^A28 | R28: =Inputs_IAS19!$C$9*(1+Inputs_IAS19!$C$3)^(A28-1) | S28: =MIN($B$7,Inputs_IAS19!$C$12)/Inputs_IAS19!$C$11*MAX(Q28-Inputs_IAS19!$C$10*R28,0) | T28: =S28*(1+Inputs_IAS19!$C$5*0.5)*(1+Inputs_IAS19!$C$5)^($B$6-A28) | U28: =IF(A28<=$B$6,P28*(1-M28/2)*T28/E28,0)
A29: 11 | B29: =Inputs_IAS19!$C$2+A29 | C29: =$B$5+A29-1 | D29: =IF(C29>=120,1,MIN(1,IF(A29<=$B$6,IF($B$4="M",Inputs_IAS19!$C$13,Inputs_IAS19!$C$14),IF($B$4="M",Inputs_IAS19!$C$15,Inputs_IAS19!$C$16))*INDEX(ILT!$B$2:$C$122,MIN(C29,120)+1,IF($B$4="M",1,2))*(1-Inputs_IAS19!$C$17)^MAX(B29-Inputs_IAS19!$C$18,0))) | E29: =E28*(1-D29) | F29: =(E28+E29)/2 | G29: =IF(A29<$B$6+1,0,IF(A29=$B$6+1,1,G28*(1+IF(B29=Inputs_IAS19!$C$7,Inputs_IAS19!$C$8,Inputs_IAS19!$C$6)))) | H29: =$B$12*G29*F29 | I29: =(1+Inputs_IAS19!$C$26)^-(A29-0.5) | J29: =H29*I29 | K29: =H29*INDEX(Curve_IAS19!$D$2:$D$101,A29) | M29: =IF(A29<=$B$6,1-E29/E28,0) | N29: =IF(A29<=$B$6,Inputs_IAS19!$C$19*IF(C29<Inputs_IAS19!$C$22,MAX(0,Inputs_IAS19!$C$20-Inputs_IAS19!$C$21*(C29-35)),0),0) | O29: =O28*(1-M29-N29) | P29: =O28*N29 | Q29: =$B$8*(1+Inputs_IAS19!$C$4)^A29 | R29: =Inputs_IAS19!$C$9*(1+Inputs_IAS19!$C$3)^(A29-1) | S29: =MIN($B$7,Inputs_IAS19!$C$12)/Inputs_IAS19!$C$11*MAX(Q29-Inputs_IAS19!$C$10*R29,0) | T29: =S29*(1+Inputs_IAS19!$C$5*0.5)*(1+Inputs_IAS19!$C$5)^($B$6-A29) | U29: =IF(A29<=$B$6,P29*(1-M29/2)*T29/E29,0)
A30: 12 | B30: =Inputs_IAS19!$C$2+A30 | C30: =$B$5+A30-1 | D30: =IF(C30>=120,1,MIN(1,IF(A30<=$B$6,IF($B$4="M",Inputs_IAS19!$C$13,Inputs_IAS19!$C$14),IF($B$4="M",Inputs_IAS19!$C$15,Inputs_IAS19!$C$16))*INDEX(ILT!$B$2:$C$122,MIN(C30,120)+1,IF($B$4="M",1,2))*(1-Inputs_IAS19!$C$17)^MAX(B30-Inputs_IAS19!$C$18,0))) | E30: =E29*(1-D30) | F30: =(E29+E30)/2 | G30: =IF(A30<$B$6+1,0,IF(A30=$B$6+1,1,G29*(1+IF(B30=Inputs_IAS19!$C$7,Inputs_IAS19!$C$8,Inputs_IAS19!$C$6)))) | H30: =$B$12*G30*F30 | I30: =(1+Inputs_IAS19!$C$26)^-(A30-0.5) | J30: =H30*I30 | K30: =H30*INDEX(Curve_IAS19!$D$2:$D$101,A30) | M30: =IF(A30<=$B$6,1-E30/E29,0) | N30: =IF(A30<=$B$6,Inputs_IAS19!$C$19*IF(C30<Inputs_IAS19!$C$22,MAX(0,Inputs_IAS19!$C$20-Inputs_IAS19!$C$21*(C30-35)),0),0) | O30: =O29*(1-M30-N30) | P30: =O29*N30 | Q30: =$B$8*(1+Inputs_IAS19!$C$4)^A30 | R30: =Inputs_IAS19!$C$9*(1+Inputs_IAS19!$C$3)^(A30-1) | S30: =MIN($B$7,Inputs_IAS19!$C$12)/Inputs_IAS19!$C$11*MAX(Q30-Inputs_IAS19!$C$10*R30,0) | T30: =S30*(1+Inputs_IAS19!$C$5*0.5)*(1+Inputs_IAS19!$C$5)^($B$6-A30) | U30: =IF(A30<=$B$6,P30*(1-M30/2)*T30/E30,0)
... A118: 100 | B118: =Inputs_IAS19!$C$2+A118 | C118: =$B$5+A118-1 | D118: =IF(C118>=120,1,MIN(1,IF(A118<=$B$6,IF($B$4="M",Inputs_IAS19!$C$13,Inputs_IAS19!$C$14),IF($B$4="M",Inputs_IAS19!$C$15,Inputs_IAS19!$C$16))*INDEX(ILT!$B$2:$C$122,MIN(C118,120)+1,IF($B$4="M",1,2))*(1-Inputs_IAS19!$C$17)^MAX(B118-Inputs_IAS19!$C$18,0))) | E118: =E117*(1-D118) | F118: =(E117+E118)/2 | G118: =IF(A118<$B$6+1,0,IF(A118=$B$6+1,1,G117*(1+IF(B118=Inputs_IAS19!$C$7,Inputs_IAS19!$C$8,Inputs_IAS19!$C$6)))) | H118: =$B$12*G118*F118 | I118: =(1+Inputs_IAS19!$C$26)^-(A118-0.5) | J118: =H118*I118 | K118: =H118*INDEX(Curve_IAS19!$D$2:$D$101,A118) | M118: =IF(A118<=$B$6,1-E118/E117,0) | N118: =IF(A118<=$B$6,Inputs_IAS19!$C$19*IF(C118<Inputs_IAS19!$C$22,MAX(0,Inputs_IAS19!$C$20-Inputs_IAS19!$C$21*(C118-35)),0),0) | O118: =O117*(1-M118-N118) | P118: =O117*N118 | Q118: =$B$8*(1+Inputs_IAS19!$C$4)^A118 | R118: =Inputs_IAS19!$C$9*(1+Inputs_IAS19!$C$3)^(A118-1) | S118: =MIN($B$7,Inputs_IAS19!$C$12)/Inputs_IAS19!$C$11*MAX(Q118-Inputs_IAS19!$C$10*R118,0) | T118: =S118*(1+Inputs_IAS19!$C$5*0.5)*(1+Inputs_IAS19!$C$5)^($B$6-A118) | U118: =IF(A118<=$B$6,P118*(1-M118/2)*T118/E118,0)

Sheet FS_Pensioner
A1: FS_Pensioner: P x increases x average survival, paid mid-year
A3: member_id | B3: M0017 | D3: Annuity cost (AAA + insurer spread) | E3: =SUM(J19:J118)
A4: sex | B4: M
A5: age x (nearest, at valuation) | B5: 72
A6: T (years to 65) | B6: 0
A7: pension in payment (2025) | B7: 20331.03
A17: t | B17: year | C17: age | D17: q | E17: survival | F17: avg survival | G17: pension index | H17: cash flow | I17: DF 1 | J17: PV 1 | K17: PV 2
A18: 0 | E18: 1 | G18: 1
A19: 1 | B19: =Inputs_Annuity!$C$2+A19 | C19: =$B$5+A19-1 | D19: =IF(C19>=120,1,MIN(1,IF(A19<=$B$6,IF($B$4="M",Inputs_Annuity!$C$13,Inputs_Annuity!$C$14),IF($B$4="M",Inputs_Annuity!$C$15,Inputs_Annuity!$C$16))*INDEX(ILT!$B$2:$C$122,MIN(C19,120)+1,IF($B$4="M",1,2))*(1-Inputs_Annuity!$C$17)^MAX(B19-Inputs_Annuity!$C$18,0))) | E19: =E18*(1-D19) | F19: =(E18+E19)/2 | G19: =G18*(1+IF(B19=Inputs_Annuity!$C$7,Inputs_Annuity!$C$8,Inputs_Annuity!$C$6)) | H19: =$B$7*G19*F19 | I19: =INDEX(Curve_Annuity!$D$2:$D$101,A19) | J19: =H19*I19
A20: 2 | B20: =Inputs_Annuity!$C$2+A20 | C20: =$B$5+A20-1 | D20: =IF(C20>=120,1,MIN(1,IF(A20<=$B$6,IF($B$4="M",Inputs_Annuity!$C$13,Inputs_Annuity!$C$14),IF($B$4="M",Inputs_Annuity!$C$15,Inputs_Annuity!$C$16))*INDEX(ILT!$B$2:$C$122,MIN(C20,120)+1,IF($B$4="M",1,2))*(1-Inputs_Annuity!$C$17)^MAX(B20-Inputs_Annuity!$C$18,0))) | E20: =E19*(1-D20) | F20: =(E19+E20)/2 | G20: =G19*(1+IF(B20=Inputs_Annuity!$C$7,Inputs_Annuity!$C$8,Inputs_Annuity!$C$6)) | H20: =$B$7*G20*F20 | I20: =INDEX(Curve_Annuity!$D$2:$D$101,A20) | J20: =H20*I20
A21: 3 | B21: =Inputs_Annuity!$C$2+A21 | C21: =$B$5+A21-1 | D21: =IF(C21>=120,1,MIN(1,IF(A21<=$B$6,IF($B$4="M",Inputs_Annuity!$C$13,Inputs_Annuity!$C$14),IF($B$4="M",Inputs_Annuity!$C$15,Inputs_Annuity!$C$16))*INDEX(ILT!$B$2:$C$122,MIN(C21,120)+1,IF($B$4="M",1,2))*(1-Inputs_Annuity!$C$17)^MAX(B21-Inputs_Annuity!$C$18,0))) | E21: =E20*(1-D21) | F21: =(E20+E21)/2 | G21: =G20*(1+IF(B21=Inputs_Annuity!$C$7,Inputs_Annuity!$C$8,Inputs_Annuity!$C$6)) | H21: =$B$7*G21*F21 | I21: =INDEX(Curve_Annuity!$D$2:$D$101,A21) | J21: =H21*I21
A22: 4 | B22: =Inputs_Annuity!$C$2+A22 | C22: =$B$5+A22-1 | D22: =IF(C22>=120,1,MIN(1,IF(A22<=$B$6,IF($B$4="M",Inputs_Annuity!$C$13,Inputs_Annuity!$C$14),IF($B$4="M",Inputs_Annuity!$C$15,Inputs_Annuity!$C$16))*INDEX(ILT!$B$2:$C$122,MIN(C22,120)+1,IF($B$4="M",1,2))*(1-Inputs_Annuity!$C$17)^MAX(B22-Inputs_Annuity!$C$18,0))) | E22: =E21*(1-D22) | F22: =(E21+E22)/2 | G22: =G21*(1+IF(B22=Inputs_Annuity!$C$7,Inputs_Annuity!$C$8,Inputs_Annuity!$C$6)) | H22: =$B$7*G22*F22 | I22: =INDEX(Curve_Annuity!$D$2:$D$101,A22) | J22: =H22*I22
A23: 5 | B23: =Inputs_Annuity!$C$2+A23 | C23: =$B$5+A23-1 | D23: =IF(C23>=120,1,MIN(1,IF(A23<=$B$6,IF($B$4="M",Inputs_Annuity!$C$13,Inputs_Annuity!$C$14),IF($B$4="M",Inputs_Annuity!$C$15,Inputs_Annuity!$C$16))*INDEX(ILT!$B$2:$C$122,MIN(C23,120)+1,IF($B$4="M",1,2))*(1-Inputs_Annuity!$C$17)^MAX(B23-Inputs_Annuity!$C$18,0))) | E23: =E22*(1-D23) | F23: =(E22+E23)/2 | G23: =G22*(1+IF(B23=Inputs_Annuity!$C$7,Inputs_Annuity!$C$8,Inputs_Annuity!$C$6)) | H23: =$B$7*G23*F23 | I23: =INDEX(Curve_Annuity!$D$2:$D$101,A23) | J23: =H23*I23
A24: 6 | B24: =Inputs_Annuity!$C$2+A24 | C24: =$B$5+A24-1 | D24: =IF(C24>=120,1,MIN(1,IF(A24<=$B$6,IF($B$4="M",Inputs_Annuity!$C$13,Inputs_Annuity!$C$14),IF($B$4="M",Inputs_Annuity!$C$15,Inputs_Annuity!$C$16))*INDEX(ILT!$B$2:$C$122,MIN(C24,120)+1,IF($B$4="M",1,2))*(1-Inputs_Annuity!$C$17)^MAX(B24-Inputs_Annuity!$C$18,0))) | E24: =E23*(1-D24) | F24: =(E23+E24)/2 | G24: =G23*(1+IF(B24=Inputs_Annuity!$C$7,Inputs_Annuity!$C$8,Inputs_Annuity!$C$6)) | H24: =$B$7*G24*F24 | I24: =INDEX(Curve_Annuity!$D$2:$D$101,A24) | J24: =H24*I24
A25: 7 | B25: =Inputs_Annuity!$C$2+A25 | C25: =$B$5+A25-1 | D25: =IF(C25>=120,1,MIN(1,IF(A25<=$B$6,IF($B$4="M",Inputs_Annuity!$C$13,Inputs_Annuity!$C$14),IF($B$4="M",Inputs_Annuity!$C$15,Inputs_Annuity!$C$16))*INDEX(ILT!$B$2:$C$122,MIN(C25,120)+1,IF($B$4="M",1,2))*(1-Inputs_Annuity!$C$17)^MAX(B25-Inputs_Annuity!$C$18,0))) | E25: =E24*(1-D25) | F25: =(E24+E25)/2 | G25: =G24*(1+IF(B25=Inputs_Annuity!$C$7,Inputs_Annuity!$C$8,Inputs_Annuity!$C$6)) | H25: =$B$7*G25*F25 | I25: =INDEX(Curve_Annuity!$D$2:$D$101,A25) | J25: =H25*I25
A26: 8 | B26: =Inputs_Annuity!$C$2+A26 | C26: =$B$5+A26-1 | D26: =IF(C26>=120,1,MIN(1,IF(A26<=$B$6,IF($B$4="M",Inputs_Annuity!$C$13,Inputs_Annuity!$C$14),IF($B$4="M",Inputs_Annuity!$C$15,Inputs_Annuity!$C$16))*INDEX(ILT!$B$2:$C$122,MIN(C26,120)+1,IF($B$4="M",1,2))*(1-Inputs_Annuity!$C$17)^MAX(B26-Inputs_Annuity!$C$18,0))) | E26: =E25*(1-D26) | F26: =(E25+E26)/2 | G26: =G25*(1+IF(B26=Inputs_Annuity!$C$7,Inputs_Annuity!$C$8,Inputs_Annuity!$C$6)) | H26: =$B$7*G26*F26 | I26: =INDEX(Curve_Annuity!$D$2:$D$101,A26) | J26: =H26*I26
A27: 9 | B27: =Inputs_Annuity!$C$2+A27 | C27: =$B$5+A27-1 | D27: =IF(C27>=120,1,MIN(1,IF(A27<=$B$6,IF($B$4="M",Inputs_Annuity!$C$13,Inputs_Annuity!$C$14),IF($B$4="M",Inputs_Annuity!$C$15,Inputs_Annuity!$C$16))*INDEX(ILT!$B$2:$C$122,MIN(C27,120)+1,IF($B$4="M",1,2))*(1-Inputs_Annuity!$C$17)^MAX(B27-Inputs_Annuity!$C$18,0))) | E27: =E26*(1-D27) | F27: =(E26+E27)/2 | G27: =G26*(1+IF(B27=Inputs_Annuity!$C$7,Inputs_Annuity!$C$8,Inputs_Annuity!$C$6)) | H27: =$B$7*G27*F27 | I27: =INDEX(Curve_Annuity!$D$2:$D$101,A27) | J27: =H27*I27
A28: 10 | B28: =Inputs_Annuity!$C$2+A28 | C28: =$B$5+A28-1 | D28: =IF(C28>=120,1,MIN(1,IF(A28<=$B$6,IF($B$4="M",Inputs_Annuity!$C$13,Inputs_Annuity!$C$14),IF($B$4="M",Inputs_Annuity!$C$15,Inputs_Annuity!$C$16))*INDEX(ILT!$B$2:$C$122,MIN(C28,120)+1,IF($B$4="M",1,2))*(1-Inputs_Annuity!$C$17)^MAX(B28-Inputs_Annuity!$C$18,0))) | E28: =E27*(1-D28) | F28: =(E27+E28)/2 | G28: =G27*(1+IF(B28=Inputs_Annuity!$C$7,Inputs_Annuity!$C$8,Inputs_Annuity!$C$6)) | H28: =$B$7*G28*F28 | I28: =INDEX(Curve_Annuity!$D$2:$D$101,A28) | J28: =H28*I28
A29: 11 | B29: =Inputs_Annuity!$C$2+A29 | C29: =$B$5+A29-1 | D29: =IF(C29>=120,1,MIN(1,IF(A29<=$B$6,IF($B$4="M",Inputs_Annuity!$C$13,Inputs_Annuity!$C$14),IF($B$4="M",Inputs_Annuity!$C$15,Inputs_Annuity!$C$16))*INDEX(ILT!$B$2:$C$122,MIN(C29,120)+1,IF($B$4="M",1,2))*(1-Inputs_Annuity!$C$17)^MAX(B29-Inputs_Annuity!$C$18,0))) | E29: =E28*(1-D29) | F29: =(E28+E29)/2 | G29: =G28*(1+IF(B29=Inputs_Annuity!$C$7,Inputs_Annuity!$C$8,Inputs_Annuity!$C$6)) | H29: =$B$7*G29*F29 | I29: =INDEX(Curve_Annuity!$D$2:$D$101,A29) | J29: =H29*I29
A30: 12 | B30: =Inputs_Annuity!$C$2+A30 | C30: =$B$5+A30-1 | D30: =IF(C30>=120,1,MIN(1,IF(A30<=$B$6,IF($B$4="M",Inputs_Annuity!$C$13,Inputs_Annuity!$C$14),IF($B$4="M",Inputs_Annuity!$C$15,Inputs_Annuity!$C$16))*INDEX(ILT!$B$2:$C$122,MIN(C30,120)+1,IF($B$4="M",1,2))*(1-Inputs_Annuity!$C$17)^MAX(B30-Inputs_Annuity!$C$18,0))) | E30: =E29*(1-D30) | F30: =(E29+E30)/2 | G30: =G29*(1+IF(B30=Inputs_Annuity!$C$7,Inputs_Annuity!$C$8,Inputs_Annuity!$C$6)) | H30: =$B$7*G30*F30 | I30: =INDEX(Curve_Annuity!$D$2:$D$101,A30) | J30: =H30*I30
... A118: 100 | B118: =Inputs_Annuity!$C$2+A118 | C118: =$B$5+A118-1 | D118: =IF(C118>=120,1,MIN(1,IF(A118<=$B$6,IF($B$4="M",Inputs_Annuity!$C$13,Inputs_Annuity!$C$14),IF($B$4="M",Inputs_Annuity!$C$15,Inputs_Annuity!$C$16))*INDEX(ILT!$B$2:$C$122,MIN(C118,120)+1,IF($B$4="M",1,2))*(1-Inputs_Annuity!$C$17)^MAX(B118-Inputs_Annuity!$C$18,0))) | E118: =E117*(1-D118) | F118: =(E117+E118)/2 | G118: =G117*(1+IF(B118=Inputs_Annuity!$C$7,Inputs_Annuity!$C$8,Inputs_Annuity!$C$6)) | H118: =$B$7*G118*F118 | I118: =INDEX(Curve_Annuity!$D$2:$D$101,A118) | J118: =H118*I118

Sheet FS_Deferred
A1: FS_Deferred: pension at exit, official revaluation to the valuation year, then r a year to 65
A3: member_id | B3: M0021 | D3: PV at 6% / 4.25% | E3: =SUM(J19:J118)
A4: sex | B4: F | D4: MVA pre | E4: =((1+Inputs_S34!$C$26)/(1+Inputs_S34!$C$27+MIN($B$6,Inputs_S34!$C$28)/Inputs_S34!$C$29*(Inputs_S34!$C$26-Inputs_S34!$C$27)))^MIN($B$6,Inputs_S34!$C$28)
A5: age x (nearest, at valuation) | B5: 50 | D5: MVA post | E5: =IF($B$6<=Inputs_S34!$C$28,Inputs_S34!$C$30*(Inputs_S34!$C$28-$B$6)/Inputs_S34!$C$28+$B$6/Inputs_S34!$C$28,1)
A6: T (years to 65) | B6: 15 | D6: Transfer value | E6: =E3*E4*E5
A7: pension at exit | B7: 3866.4
A8: exit year | B8: 2020
A9: exit month | B9: 7
A10: exit day | B10: 20
A11: complete months to 31 Dec | B11: =12-B9+IF(B10=1,1,0)
A12: revaluation factor to valuation year | B12: =N22
A13: pension at valuation date | B13: =B7*B12
A14: pension at 65 x loading | B14: =B13*(1+Inputs_S34!$C$5)^B6*(1+IF($B$4="M",Inputs_S34!$C$23,Inputs_S34!$C$24))^MAX(Inputs_S34!$C$2+$B$6-Inputs_S34!$C$25,0)
M16: rev. year | N16: factor
A17: t | B17: year | C17: age | D17: q | E17: survival | F17: avg survival | G17: pension index | H17: cash flow | I17: DF 1 | J17: PV 1 | K17: PV 2 | M17: 2020 | N17: =1+INDEX(Revaluation!$B:$B,M17-1996+2)/100*$B$11/12
A18: 0 | E18: 1 | G18: 0 | M18: 2021 | N18: =N17*(1+INDEX(Revaluation!$B:$B,M18-1996+2)/100)
A19: 1 | B19: =Inputs_S34!$C$2+A19 | C19: =$B$5+A19-1 | D19: =IF(C19>=120,1,MIN(1,IF(A19<=$B$6,IF($B$4="M",Inputs_S34!$C$13,Inputs_S34!$C$14),IF($B$4="M",Inputs_S34!$C$15,Inputs_S34!$C$16))*INDEX(ILT!$B$2:$C$122,MIN(C19,120)+1,IF($B$4="M",1,2))*(1-Inputs_S34!$C$17)^MAX(B19-Inputs_S34!$C$18,0))) | E19: =E18*(1-D19) | F19: =(E18+E19)/2 | G19: =IF(A19<$B$6+1,0,IF(A19=$B$6+1,1,G18*(1+IF(B19=Inputs_S34!$C$7,Inputs_S34!$C$8,Inputs_S34!$C$6)))) | H19: =$B$14*G19*F19 | I19: =(1+Inputs_S34!$C$26)^-MIN(A19-0.5,$B$6)*(1+Inputs_S34!$C$27)^-MAX(A19-0.5-$B$6,0) | J19: =H19*I19 | M19: 2022 | N19: =N18*(1+INDEX(Revaluation!$B:$B,M19-1996+2)/100)
A20: 2 | B20: =Inputs_S34!$C$2+A20 | C20: =$B$5+A20-1 | D20: =IF(C20>=120,1,MIN(1,IF(A20<=$B$6,IF($B$4="M",Inputs_S34!$C$13,Inputs_S34!$C$14),IF($B$4="M",Inputs_S34!$C$15,Inputs_S34!$C$16))*INDEX(ILT!$B$2:$C$122,MIN(C20,120)+1,IF($B$4="M",1,2))*(1-Inputs_S34!$C$17)^MAX(B20-Inputs_S34!$C$18,0))) | E20: =E19*(1-D20) | F20: =(E19+E20)/2 | G20: =IF(A20<$B$6+1,0,IF(A20=$B$6+1,1,G19*(1+IF(B20=Inputs_S34!$C$7,Inputs_S34!$C$8,Inputs_S34!$C$6)))) | H20: =$B$14*G20*F20 | I20: =(1+Inputs_S34!$C$26)^-MIN(A20-0.5,$B$6)*(1+Inputs_S34!$C$27)^-MAX(A20-0.5-$B$6,0) | J20: =H20*I20 | M20: 2023 | N20: =N19*(1+INDEX(Revaluation!$B:$B,M20-1996+2)/100)
A21: 3 | B21: =Inputs_S34!$C$2+A21 | C21: =$B$5+A21-1 | D21: =IF(C21>=120,1,MIN(1,IF(A21<=$B$6,IF($B$4="M",Inputs_S34!$C$13,Inputs_S34!$C$14),IF($B$4="M",Inputs_S34!$C$15,Inputs_S34!$C$16))*INDEX(ILT!$B$2:$C$122,MIN(C21,120)+1,IF($B$4="M",1,2))*(1-Inputs_S34!$C$17)^MAX(B21-Inputs_S34!$C$18,0))) | E21: =E20*(1-D21) | F21: =(E20+E21)/2 | G21: =IF(A21<$B$6+1,0,IF(A21=$B$6+1,1,G20*(1+IF(B21=Inputs_S34!$C$7,Inputs_S34!$C$8,Inputs_S34!$C$6)))) | H21: =$B$14*G21*F21 | I21: =(1+Inputs_S34!$C$26)^-MIN(A21-0.5,$B$6)*(1+Inputs_S34!$C$27)^-MAX(A21-0.5-$B$6,0) | J21: =H21*I21 | M21: 2024 | N21: =N20*(1+INDEX(Revaluation!$B:$B,M21-1996+2)/100)
A22: 4 | B22: =Inputs_S34!$C$2+A22 | C22: =$B$5+A22-1 | D22: =IF(C22>=120,1,MIN(1,IF(A22<=$B$6,IF($B$4="M",Inputs_S34!$C$13,Inputs_S34!$C$14),IF($B$4="M",Inputs_S34!$C$15,Inputs_S34!$C$16))*INDEX(ILT!$B$2:$C$122,MIN(C22,120)+1,IF($B$4="M",1,2))*(1-Inputs_S34!$C$17)^MAX(B22-Inputs_S34!$C$18,0))) | E22: =E21*(1-D22) | F22: =(E21+E22)/2 | G22: =IF(A22<$B$6+1,0,IF(A22=$B$6+1,1,G21*(1+IF(B22=Inputs_S34!$C$7,Inputs_S34!$C$8,Inputs_S34!$C$6)))) | H22: =$B$14*G22*F22 | I22: =(1+Inputs_S34!$C$26)^-MIN(A22-0.5,$B$6)*(1+Inputs_S34!$C$27)^-MAX(A22-0.5-$B$6,0) | J22: =H22*I22 | M22: 2025 | N22: =N21*(1+INDEX(Revaluation!$B:$B,M22-1996+2)/100)
A23: 5 | B23: =Inputs_S34!$C$2+A23 | C23: =$B$5+A23-1 | D23: =IF(C23>=120,1,MIN(1,IF(A23<=$B$6,IF($B$4="M",Inputs_S34!$C$13,Inputs_S34!$C$14),IF($B$4="M",Inputs_S34!$C$15,Inputs_S34!$C$16))*INDEX(ILT!$B$2:$C$122,MIN(C23,120)+1,IF($B$4="M",1,2))*(1-Inputs_S34!$C$17)^MAX(B23-Inputs_S34!$C$18,0))) | E23: =E22*(1-D23) | F23: =(E22+E23)/2 | G23: =IF(A23<$B$6+1,0,IF(A23=$B$6+1,1,G22*(1+IF(B23=Inputs_S34!$C$7,Inputs_S34!$C$8,Inputs_S34!$C$6)))) | H23: =$B$14*G23*F23 | I23: =(1+Inputs_S34!$C$26)^-MIN(A23-0.5,$B$6)*(1+Inputs_S34!$C$27)^-MAX(A23-0.5-$B$6,0) | J23: =H23*I23
A24: 6 | B24: =Inputs_S34!$C$2+A24 | C24: =$B$5+A24-1 | D24: =IF(C24>=120,1,MIN(1,IF(A24<=$B$6,IF($B$4="M",Inputs_S34!$C$13,Inputs_S34!$C$14),IF($B$4="M",Inputs_S34!$C$15,Inputs_S34!$C$16))*INDEX(ILT!$B$2:$C$122,MIN(C24,120)+1,IF($B$4="M",1,2))*(1-Inputs_S34!$C$17)^MAX(B24-Inputs_S34!$C$18,0))) | E24: =E23*(1-D24) | F24: =(E23+E24)/2 | G24: =IF(A24<$B$6+1,0,IF(A24=$B$6+1,1,G23*(1+IF(B24=Inputs_S34!$C$7,Inputs_S34!$C$8,Inputs_S34!$C$6)))) | H24: =$B$14*G24*F24 | I24: =(1+Inputs_S34!$C$26)^-MIN(A24-0.5,$B$6)*(1+Inputs_S34!$C$27)^-MAX(A24-0.5-$B$6,0) | J24: =H24*I24
A25: 7 | B25: =Inputs_S34!$C$2+A25 | C25: =$B$5+A25-1 | D25: =IF(C25>=120,1,MIN(1,IF(A25<=$B$6,IF($B$4="M",Inputs_S34!$C$13,Inputs_S34!$C$14),IF($B$4="M",Inputs_S34!$C$15,Inputs_S34!$C$16))*INDEX(ILT!$B$2:$C$122,MIN(C25,120)+1,IF($B$4="M",1,2))*(1-Inputs_S34!$C$17)^MAX(B25-Inputs_S34!$C$18,0))) | E25: =E24*(1-D25) | F25: =(E24+E25)/2 | G25: =IF(A25<$B$6+1,0,IF(A25=$B$6+1,1,G24*(1+IF(B25=Inputs_S34!$C$7,Inputs_S34!$C$8,Inputs_S34!$C$6)))) | H25: =$B$14*G25*F25 | I25: =(1+Inputs_S34!$C$26)^-MIN(A25-0.5,$B$6)*(1+Inputs_S34!$C$27)^-MAX(A25-0.5-$B$6,0) | J25: =H25*I25
A26: 8 | B26: =Inputs_S34!$C$2+A26 | C26: =$B$5+A26-1 | D26: =IF(C26>=120,1,MIN(1,IF(A26<=$B$6,IF($B$4="M",Inputs_S34!$C$13,Inputs_S34!$C$14),IF($B$4="M",Inputs_S34!$C$15,Inputs_S34!$C$16))*INDEX(ILT!$B$2:$C$122,MIN(C26,120)+1,IF($B$4="M",1,2))*(1-Inputs_S34!$C$17)^MAX(B26-Inputs_S34!$C$18,0))) | E26: =E25*(1-D26) | F26: =(E25+E26)/2 | G26: =IF(A26<$B$6+1,0,IF(A26=$B$6+1,1,G25*(1+IF(B26=Inputs_S34!$C$7,Inputs_S34!$C$8,Inputs_S34!$C$6)))) | H26: =$B$14*G26*F26 | I26: =(1+Inputs_S34!$C$26)^-MIN(A26-0.5,$B$6)*(1+Inputs_S34!$C$27)^-MAX(A26-0.5-$B$6,0) | J26: =H26*I26
A27: 9 | B27: =Inputs_S34!$C$2+A27 | C27: =$B$5+A27-1 | D27: =IF(C27>=120,1,MIN(1,IF(A27<=$B$6,IF($B$4="M",Inputs_S34!$C$13,Inputs_S34!$C$14),IF($B$4="M",Inputs_S34!$C$15,Inputs_S34!$C$16))*INDEX(ILT!$B$2:$C$122,MIN(C27,120)+1,IF($B$4="M",1,2))*(1-Inputs_S34!$C$17)^MAX(B27-Inputs_S34!$C$18,0))) | E27: =E26*(1-D27) | F27: =(E26+E27)/2 | G27: =IF(A27<$B$6+1,0,IF(A27=$B$6+1,1,G26*(1+IF(B27=Inputs_S34!$C$7,Inputs_S34!$C$8,Inputs_S34!$C$6)))) | H27: =$B$14*G27*F27 | I27: =(1+Inputs_S34!$C$26)^-MIN(A27-0.5,$B$6)*(1+Inputs_S34!$C$27)^-MAX(A27-0.5-$B$6,0) | J27: =H27*I27
A28: 10 | B28: =Inputs_S34!$C$2+A28 | C28: =$B$5+A28-1 | D28: =IF(C28>=120,1,MIN(1,IF(A28<=$B$6,IF($B$4="M",Inputs_S34!$C$13,Inputs_S34!$C$14),IF($B$4="M",Inputs_S34!$C$15,Inputs_S34!$C$16))*INDEX(ILT!$B$2:$C$122,MIN(C28,120)+1,IF($B$4="M",1,2))*(1-Inputs_S34!$C$17)^MAX(B28-Inputs_S34!$C$18,0))) | E28: =E27*(1-D28) | F28: =(E27+E28)/2 | G28: =IF(A28<$B$6+1,0,IF(A28=$B$6+1,1,G27*(1+IF(B28=Inputs_S34!$C$7,Inputs_S34!$C$8,Inputs_S34!$C$6)))) | H28: =$B$14*G28*F28 | I28: =(1+Inputs_S34!$C$26)^-MIN(A28-0.5,$B$6)*(1+Inputs_S34!$C$27)^-MAX(A28-0.5-$B$6,0) | J28: =H28*I28
A29: 11 | B29: =Inputs_S34!$C$2+A29 | C29: =$B$5+A29-1 | D29: =IF(C29>=120,1,MIN(1,IF(A29<=$B$6,IF($B$4="M",Inputs_S34!$C$13,Inputs_S34!$C$14),IF($B$4="M",Inputs_S34!$C$15,Inputs_S34!$C$16))*INDEX(ILT!$B$2:$C$122,MIN(C29,120)+1,IF($B$4="M",1,2))*(1-Inputs_S34!$C$17)^MAX(B29-Inputs_S34!$C$18,0))) | E29: =E28*(1-D29) | F29: =(E28+E29)/2 | G29: =IF(A29<$B$6+1,0,IF(A29=$B$6+1,1,G28*(1+IF(B29=Inputs_S34!$C$7,Inputs_S34!$C$8,Inputs_S34!$C$6)))) | H29: =$B$14*G29*F29 | I29: =(1+Inputs_S34!$C$26)^-MIN(A29-0.5,$B$6)*(1+Inputs_S34!$C$27)^-MAX(A29-0.5-$B$6,0) | J29: =H29*I29
A30: 12 | B30: =Inputs_S34!$C$2+A30 | C30: =$B$5+A30-1 | D30: =IF(C30>=120,1,MIN(1,IF(A30<=$B$6,IF($B$4="M",Inputs_S34!$C$13,Inputs_S34!$C$14),IF($B$4="M",Inputs_S34!$C$15,Inputs_S34!$C$16))*INDEX(ILT!$B$2:$C$122,MIN(C30,120)+1,IF($B$4="M",1,2))*(1-Inputs_S34!$C$17)^MAX(B30-Inputs_S34!$C$18,0))) | E30: =E29*(1-D30) | F30: =(E29+E30)/2 | G30: =IF(A30<$B$6+1,0,IF(A30=$B$6+1,1,G29*(1+IF(B30=Inputs_S34!$C$7,Inputs_S34!$C$8,Inputs_S34!$C$6)))) | H30: =$B$14*G30*F30 | I30: =(1+Inputs_S34!$C$26)^-MIN(A30-0.5,$B$6)*(1+Inputs_S34!$C$27)^-MAX(A30-0.5-$B$6,0) | J30: =H30*I30
A31: 13 | B31: =Inputs_S34!$C$2+A31 | C31: =$B$5+A31-1 | D31: =IF(C31>=120,1,MIN(1,IF(A31<=$B$6,IF($B$4="M",Inputs_S34!$C$13,Inputs_S34!$C$14),IF($B$4="M",Inputs_S34!$C$15,Inputs_S34!$C$16))*INDEX(ILT!$B$2:$C$122,MIN(C31,120)+1,IF($B$4="M",1,2))*(1-Inputs_S34!$C$17)^MAX(B31-Inputs_S34!$C$18,0))) | E31: =E30*(1-D31) | F31: =(E30+E31)/2 | G31: =IF(A31<$B$6+1,0,IF(A31=$B$6+1,1,G30*(1+IF(B31=Inputs_S34!$C$7,Inputs_S34!$C$8,Inputs_S34!$C$6)))) | H31: =$B$14*G31*F31 | I31: =(1+Inputs_S34!$C$26)^-MIN(A31-0.5,$B$6)*(1+Inputs_S34!$C$27)^-MAX(A31-0.5-$B$6,0) | J31: =H31*I31
A32: 14 | B32: =Inputs_S34!$C$2+A32 | C32: =$B$5+A32-1 | D32: =IF(C32>=120,1,MIN(1,IF(A32<=$B$6,IF($B$4="M",Inputs_S34!$C$13,Inputs_S34!$C$14),IF($B$4="M",Inputs_S34!$C$15,Inputs_S34!$C$16))*INDEX(ILT!$B$2:$C$122,MIN(C32,120)+1,IF($B$4="M",1,2))*(1-Inputs_S34!$C$17)^MAX(B32-Inputs_S34!$C$18,0))) | E32: =E31*(1-D32) | F32: =(E31+E32)/2 | G32: =IF(A32<$B$6+1,0,IF(A32=$B$6+1,1,G31*(1+IF(B32=Inputs_S34!$C$7,Inputs_S34!$C$8,Inputs_S34!$C$6)))) | H32: =$B$14*G32*F32 | I32: =(1+Inputs_S34!$C$26)^-MIN(A32-0.5,$B$6)*(1+Inputs_S34!$C$27)^-MAX(A32-0.5-$B$6,0) | J32: =H32*I32
